Workbook
Name \0: #REF!
Name \1: #REF!
Name \2: #REF!
Name \a: #REF!
Name \a: #N/A
Name \b: #N/A
Name \c: #N/A
Name \d: #N/A
Name \e: #N/A
Name \f: #N/A
Name \g: #N/A
Name \h: #N/A
Name \i: #N/A
Name \j: #N/A
Name \k: #REF!
Name \l: #REF!
Name \m: #N/A
Name \n: #REF!
Name \O: #REF!
Name \p: #N/A
Name \q: #N/A
Name \r: #N/A
Name \s: #N/A
Name \t: #N/A
Name \u: #N/A
Name \v: #N/A
Name \w: #N/A
Name \x: #N/A
Name \z: #N/A
Name _: #REF!
Name _______F99000: #REF!
Name ______F99000: #REF!
Name ____COD1: #REF!
Name ____COD10: #REF!
Name ____COD11: #REF!
Name ____COD13: #REF!
Name ____COD16: #REF!
Name ____COD17: #REF!
Name ____COD21: #REF!
Name ____COD23: #REF!
Name ____COD24: #REF!
Name ____COD28: #REF!
Name ____COD29: #REF!
Name ____COD32: #REF!
Name ____COD35: #REF!
Name ____COD36: #REF!
Name ____COD37: #REF!
Name ____COD41: #REF!
Name ____COD42: #REF!
Name ____COD43: #REF!
Name ____COD44: #REF!
Name ____COD46: #REF!
Name ____COD47: #REF!
Name ____COD49: #REF!
Name ____COD50: #REF!
Name ____COD55: #REF!
Name ____COD60: #REF!
Name ____COD62: #REF!
Name ____COD65: #REF!
Name ____COD66: #REF!

Sheet PREMISSAS
B2: PREMISSAS CONSIDERADAS - MAIO 2026
D6: A distribuição de quantitativos na linha do tempo foi feita com base nos prazos previstos no cronograma da obra postado na base do Primavera
D11: As SS's em revisão orçamentária e de cronograma não foram consideradas;
D16: As SS's em fase de planejamento no SAMC na data de fechamento 01/05 não foram consideradas
D22: Não foram consideradas retenções ou devoluções por data book
B28: SS-41/2026 | D28: IN-5250-24-092 - PT-200 - Civil e Fundações | J28: Em replanejamento - Revisão de projetos
B29: SS-42/2026 | D29: IN-5250-24-092 - PT-200 - Civil e Arquitetura | J29: =J28 -> Em replanejamento - Revisão de projetos
B30: SS-145/2025 | D30: IN - 5250-24-074 - Adequações para Recebimento de C5+ - Civil | J30: Em replanejamento - Revisão de projetos
B31: SS-146/2025 | D31: IN - 5250-24-074 - Adequações para Recebimento de C5+ - Mecânica | J31: Em replanejamento - Revisão de projetos
B32: SS-147/2025 | D32: IN - 5250-24-074 - Adequações para Recebimento de C5+ - Elétrica | J32: Em replanejamento - Revisão de projetos
B33: SS-125/2026 | D33: U-110 - DEMOLIÇÃO FUNDAÇÃO - 110-R-01 | J33: Foram consideradas, porém na data do fechamento foi enviadas uma revisão dos projetos via SAMC
B34: SS-126/2026 | D34: U-110 - CONSTRUÇÃO FUNDAÇÃO - 110-R-01 | J34: Foram consideradas, porém na data do fechamento foi enviadas uma revisão dos projetos via SAMC

Sheet RESUMO CRON FINANC
B4: TIME LINE - OBRAS SERVIÇOS | F4: MAIO | G4: JUNHO | H4: JULHO | I4: AGOSTO | J4: SETEMBRO | K4: OUTUBRO | L4: NOVEMBRO | M4: DEZEMBRO | N4: TOTAL MAIO A DEZ/2026
B5: ITEM | D5: DESCRIÇÃO | E5: DISCIPLINA
B6: 1 | C6: SS-1/2026 | D6: Adequação Escadas de Marinheiro - Execução - UN 01,102,108,109,209 - UDAV 01/02 | E6: Civil | F6: ='CRONO SERV'!X7 -> 8448.9511 | G6: ='CRONO SERV'!Y7 -> 22525.794 | H6: ='CRONO SERV'!Z7 -> 22525.794 | I6: ='CRONO SERV'!AA7 -> 27860.851 | J6: ='CRONO SERV'!AB7 -> 26675.282 | K6: ='CRONO SERV'!AC7 -> 26400.231 | L6: ='CRONO SERV'!AD7 -> 0 | M6: ='CRONO SERV'!AE7 -> 0 | N6: =SUM(F6:M6) -> 134436.9
B7: 2 | C7: SS-2/2026 | D7: IN-5250-24-092 - PT-200 - Escavação Manual para Pré Furos e Fundação | E7: Civil | F7: ='CRONO SERV'!X12 -> 86040.747 | G7: ='CRONO SERV'!Y12 -> 47782.443 | H7: ='CRONO SERV'!Z12 -> 0 | I7: ='CRONO SERV'!AA12 -> 0 | J7: ='CRONO SERV'!AB12 -> 0 | K7: ='CRONO SERV'!AC12 -> 0 | L7: ='CRONO SERV'!AD12 -> 0 | M7: ='CRONO SERV'!AE12 -> 0 | N7: =SUM(F7:M7) -> 133823.19
B8: 3 | C8: SS-14/2026 | D8: PMBC - 5250-26-100 - ALTERAÇÕES - HAZOP DA U-001 E U-101 | E8: Mecânica | F8: ='CRONO SERV'!X24 -> 7793.8298 | G8: ='CRONO SERV'!Y24 -> 11371.202 | H8: ='CRONO SERV'!Z24 -> 0 | I8: ='CRONO SERV'!AA24 -> 0 | J8: ='CRONO SERV'!AB24 -> 0 | K8: ='CRONO SERV'!AC24 -> 0 | L8: ='CRONO SERV'!AD24 -> 0 | M8: ='CRONO SERV'!AE24 -> 0 | N8: =SUM(F8:M8) -> 19165.032
B9: 4 | C9: SS-36/2026 | D9: Manutenção Civil - Linha do Flare na Av. 8 | E9: Civil | F9: ='CRONO SERV'!X31 -> 117974.19 | G9: ='CRONO SERV'!Y31 -> 73101.436 | H9: ='CRONO SERV'!Z31 -> 89929.793 | I9: ='CRONO SERV'!AA31 -> 0 | J9: ='CRONO SERV'!AB31 -> 0 | K9: ='CRONO SERV'!AC31 -> 0 | L9: ='CRONO SERV'!AD31 -> 0 | M9: ='CRONO SERV'!AE31 -> 0 | N9: =SUM(F9:M9) -> 281005.42
B10: 5 | C10: SS-39/2026 | D10: IN-5250-24-092 - PT-200 - Estrutura Metálica - Fabricação | E10: Mecânica | F10: ='CRONO SERV'!X37 -> 522626.67 | G10: ='CRONO SERV'!Y37 -> 2891867.6 | H10: ='CRONO SERV'!Z37 -> 3553861.4 | I10: ='CRONO SERV'!AA37 -> 592310.23 | J10: ='CRONO SERV'!AB37 -> 0 | K10: ='CRONO SERV'!AC37 -> 0 | L10: ='CRONO SERV'!AD37 -> 0 | M10: ='CRONO SERV'!AE37 -> 0 | N10: =SUM(F10:M10) -> 7560665.9
B11: 6 | C11: SS-44/2026 | D11: IN - 5250-24-085 - Phase-Out do Diesel S500 - Mudança 2.1 - Fabricação (Tubovias) | E11: Mecânica | F11: ='CRONO SERV'!X39 -> 383499.72 | G11: ='CRONO SERV'!Y39 -> 161818.85 | H11: ='CRONO SERV'!Z39 -> 0 | I11: ='CRONO SERV'!AA39 -> 0 | J11: ='CRONO SERV'!AB39 -> 0 | K11: ='CRONO SERV'!AC39 -> 0 | L11: ='CRONO SERV'!AD39 -> 0 | M11: ='CRONO SERV'!AE39 -> 0 | N11: =SUM(F11:M11) -> 545318.56
B12: 7 | C12: SS-45/2026 | D12: IN - 5250-24-085 - Phase-Out do Diesel S500 - Mudança 2.1 - Montagem (Tubovias) | E12: Mecânica | F12: ='CRONO SERV'!X43 -> 128043.83 | G12: ='CRONO SERV'!Y43 -> 161833.33 | H12: ='CRONO SERV'!Z43 -> 679455.25 | I12: ='CRONO SERV'!AA43 -> 853.59637 | J12: ='CRONO SERV'!AB43 -> 0 | K12: ='CRONO SERV'!AC43 -> 0 | L12: ='CRONO SERV'!AD43 -> 0 | M12: ='CRONO SERV'!AE43 -> 0 | N12: =SUM(F12:M12) -> 970186
B13: 8 | C13: SS-60/2025 | D13: IN-5250-25-014 - ETDI - DESARENADOR | E13: Civil | F13: ='CRONO SERV'!X47 -> 81934.92 | G13: ='CRONO SERV'!Y47 -> 0 | H13: ='CRONO SERV'!Z47 -> 0 | I13: ='CRONO SERV'!AA47 -> 0 | J13: ='CRONO SERV'!AB47 -> 0 | K13: ='CRONO SERV'!AC47 -> 0 | L13: ='CRONO SERV'!AD47 -> 0 | M13: ='CRONO SERV'!AE47 -> 0 | N13: =SUM(F13:M13) -> 81934.92
B14: 9 | C14: SS-61/2025 | D14: IN-5250-20-001 - ETDI - REDE CONTAMINADA | E14: Civil | F14: ='CRONO SERV'!X71 -> 1040.7412 | G14: ='CRONO SERV'!Y71 -> 0 | H14: ='CRONO SERV'!Z71 -> 0 | I14: ='CRONO SERV'!AA71 -> 0 | J14: ='CRONO SERV'!AB71 -> 0 | K14: ='CRONO SERV'!AC71 -> 0 | L14: ='CRONO SERV'!AD71 -> 0 | M14: ='CRONO SERV'!AE71 -> 0 | N14: =SUM(F14:M14) -> 1040.7412
B15: 10 | C15: SS-62/2025 | D15: IN - 5250-25-005 - ETDI - FRENTE 01 - BOMBAS DO PPI - ELÉTRICA | E15: Elétrica | F15: ='CRONO SERV'!X89 -> 0 | G15: ='CRONO SERV'!Y89 -> 73329.335 | H15: ='CRONO SERV'!Z89 -> 0 | I15: ='CRONO SERV'!AA89 -> 0 | J15: ='CRONO SERV'!AB89 -> 0 | K15: ='CRONO SERV'!AC89 -> 0 | L15: ='CRONO SERV'!AD89 -> 0 | M15: ='CRONO SERV'!AE89 -> 0 | N15: =SUM(F15:M15) -> 73329.335
B16: 11 | C16: SS-63/2026 | D16: Rede Envelopada - Armazéns S5 x S6 | E16: Civil | F16: ='CRONO SERV'!X121 -> 3242.5638 | G16: ='CRONO SERV'!Y121 -> 112386.9 | H16: ='CRONO SERV'!Z121 -> 83276.543 | I16: ='CRONO SERV'!AA121 -> 97700.247 | J16: ='CRONO SERV'!AB121 -> 0 | K16: ='CRONO SERV'!AC121 -> 0 | L16: ='CRONO SERV'!AD121 -> 0 | M16: ='CRONO SERV'!AE121 -> 0 | N16: =SUM(F16:M16) -> 296606.26
B17: 12 | C17: SS-65/2026 | D17: ATIVIDADE HS - LIMPEZA DE ROTA - ÁREA ETE | E17: Civil | F17: ='CRONO SERV'!X136 -> 0 | G17: ='CRONO SERV'!Y136 -> 0 | H17: ='CRONO SERV'!Z136 -> 0 | I17: ='CRONO SERV'!AA136 -> 179307.06 | J17: ='CRONO SERV'!AB136 -> 44826.766 | K17: ='CRONO SERV'!AC136 -> 0 | L17: ='CRONO SERV'!AD136 -> 0 | M17: ='CRONO SERV'!AE136 -> 0 | N17: =SUM(F17:M17) -> 224133.83
B18: 13 | C18: SS-66/2026 | D18: CALDEIRAS 0121-F-001 ABC - FUNDAÇÃO PARA GRUA | E18: Civil | F18: ='CRONO SERV'!X138 -> 714181.15 | G18: ='CRONO SERV'!Y138 -> 375135.62 | H18: ='CRONO SERV'!Z138 -> 40076.069 | I18: ='CRONO SERV'!AA138 -> 0 | J18: ='CRONO SERV'!AB138 -> 0 | K18: ='CRONO SERV'!AC138 -> 0 | L18: ='CRONO SERV'!AD138 -> 0 | M18: ='CRONO SERV'!AE138 -> 0 | N18: =SUM(F18:M18) -> 1129392.8
B19: 14 | C19: SS-67/2026 | D19: IN-5250-24-062 - Adequações CEM´s - Mudança 1 - U-003 (Instrumentação) | E19: Elétrica | F19: ='CRONO SERV'!X156 -> 14097.133 | G19: ='CRONO SERV'!Y156 -> 0 | H19: ='CRONO SERV'!Z156 -> 0 | I19: ='CRONO SERV'!AA156 -> 0 | J19: ='CRONO SERV'!AB156 -> 0 | K19: ='CRONO SERV'!AC156 -> 0 | L19: ='CRONO SERV'!AD156 -> 0 | M19: ='CRONO SERV'!AE156 -> 0 | N19: =SUM(F19:M19) -> 14097.133
B20: 15 | C20: SS-68 69/2026 | D20: IN-5250-24-062 - Adequações CEM´s - Mudança 2 - U-103 (Elétrica e Instrumentação ) | E20: Elétrica | F20: ='CRONO SERV'!X162 -> 0 | G20: ='CRONO SERV'!Y162 -> 13706.927 | H20: ='CRONO SERV'!Z162 -> 4781.6844 | I20: ='CRONO SERV'!AA162 -> 0 | J20: ='CRONO SERV'!AB162 -> 0 | K20: ='CRONO SERV'!AC162 -> 0 | L20: ='CRONO SERV'!AD162 -> 0 | M20: ='CRONO SERV'!AE162 -> 0 | N20: =SUM(F20:M20) -> 18488.612
B21: 16 | C21: SS-70 71/2026 | D21: IN-5250-24-062 - Adequações CEM´s - Mudança 3 - U-114 (Elétrica e Instrumentação) | E21: Elétrica | F21: ='CRONO SERV'!X171 -> 29525.834 | G21: ='CRONO SERV'!Y171 -> 0 | H21: ='CRONO SERV'!Z171 -> 0 | I21: ='CRONO SERV'!AA171 -> 0 | J21: ='CRONO SERV'!AB171 -> 0 | K21: ='CRONO SERV'!AC171 -> 0 | L21: ='CRONO SERV'!AD171 -> 0 | M21: ='CRONO SERV'!AE171 -> 0 | N21: =SUM(F21:M21) -> 29525.834
B22: 17 | C22: SS-72/2026 | D22: IN-5250-24-062 - Adequações CEM´s - Mudança 4 - U-121 (Instrumentação) | E22: Elétrica | F22: ='CRONO SERV'!X181 -> 0 | G22: ='CRONO SERV'!Y181 -> 0 | H22: ='CRONO SERV'!Z181 -> 30130.966 | I22: ='CRONO SERV'!AA181 -> 0 | J22: ='CRONO SERV'!AB181 -> 0 | K22: ='CRONO SERV'!AC181 -> 0 | L22: ='CRONO SERV'!AD181 -> 0 | M22: ='CRONO SERV'!AE181 -> 0 | N22: =SUM(F22:M22) -> 30130.966
B23: 18 | C23: SS-73/2025 | D23: IN - 5250-20-001 - ETDI - BOMBAS DO PPI - CIVIL | E23: Civil | F23: ='CRONO SERV'!X190 -> 0 | G23: ='CRONO SERV'!Y190 -> 0 | H23: ='CRONO SERV'!Z190 -> 0 | I23: ='CRONO SERV'!AA190 -> 0 | J23: ='CRONO SERV'!AB190 -> 0 | K23: ='CRONO SERV'!AC190 -> 0 | L23: ='CRONO SERV'!AD190 -> 0 | M23: ='CRONO SERV'!AE190 -> 0 | N23: =SUM(F23:M23) -> 0
B24: 19 | C24: SS-74/2025 | D24: IN-5250-25-015 - ETDI - CONTAMINADA FASE 2 - CIVIL | E24: Civil | F24: ='CRONO SERV'!X208 -> 387702.51 | G24: ='CRONO SERV'!Y208 -> 131277.49 | H24: ='CRONO SERV'!Z208 -> 137786.13 | I24: ='CRONO SERV'!AA208 -> 0 | J24: ='CRONO SERV'!AB208 -> 0 | K24: ='CRONO SERV'!AC208 -> 0 | L24: ='CRONO SERV'!AD208 -> 0 | M24: ='CRONO SERV'!AE208 -> 0 | N24: =SUM(F24:M24) -> 656766.13
B25: 20 | C25: SS-79/2026 | D25: UNIDADE 47 - TANQUE DE ÁGUA ÁCIDA | E25: Civil | F25: ='CRONO SERV'!X238 -> 0 | G25: ='CRONO SERV'!Y238 -> 135876.68 | H25: ='CRONO SERV'!Z238 -> 95896.971 | I25: ='CRONO SERV'!AA238 -> 0 | J25: ='CRONO SERV'!AB238 -> 0 | K25: ='CRONO SERV'!AC238 -> 0 | L25: ='CRONO SERV'!AD238 -> 0 | M25: ='CRONO SERV'!AE238 -> 0 | N25: =SUM(F25:M25) -> 231773.66
B26: 21 | C26: SS-80/2026 | D26: FURO DE SONDAGEM - REATOR 110-R-01 | E26: Civil | F26: ='CRONO SERV'!X247 -> 8280.3072 | G26: ='CRONO SERV'!Y247 -> 0 | H26: ='CRONO SERV'!Z247 -> 0 | I26: ='CRONO SERV'!AA247 -> 0 | J26: ='CRONO SERV'!AB247 -> 0 | K26: ='CRONO SERV'!AC247 -> 0 | L26: ='CRONO SERV'!AD247 -> 0 | M26: ='CRONO SERV'!AE247 -> 0 | N26: =SUM(F26:M26) -> 8280.3072
B27: 22 | C27: SS-89/2026 | D27: Manutenção Civil - PÁTIO DE ENXOFRE | E27: Civil | F27: ='CRONO SERV'!X250 -> 0 | G27: ='CRONO SERV'!Y250 -> 116700.07 | H27: ='CRONO SERV'!Z250 -> 277162.67 | I27: ='CRONO SERV'!AA250 -> 320925.2 | J27: ='CRONO SERV'!AB250 -> 364687.72 | K27: ='CRONO SERV'!AC250 -> 379275.23 | L27: ='CRONO SERV'!AD250 -> 0 | M27: ='CRONO SERV'!AE250 -> 0 | N27: =SUM(F27:M27) -> 1458750.9
B28: 23 | C28: SS-90/2026 | D28: Manutenção Civil - CANAL DE PINTADOS | E28: Civil | F28: ='CRONO SERV'!X264 -> 0 | G28: ='CRONO SERV'!Y264 -> 48571.587 | H28: ='CRONO SERV'!Z264 -> 73462.333 | I28: ='CRONO SERV'!AA264 -> 73462.333 | J28: ='CRONO SERV'!AB264 -> 163165.63 | K28: ='CRONO SERV'!AC264 -> 180615.52 | L28: ='CRONO SERV'!AD264 -> 170662.9 | M28: ='CRONO SERV'!AE264 -> 241392.09 | N28: =SUM(F28:M28) -> 951332.39
B29: 24 | C29: SS-94/2025 | D29: IN - 5250-20-001 - ETDI - BOMBAS DO PPI - MECANICA | E29: Mecânica | F29: ='CRONO SERV'!X273 -> 66546.757 | G29: ='CRONO SERV'!Y273 -> 412396.24 | H29: ='CRONO SERV'!Z273 -> 0 | I29: ='CRONO SERV'!AA273 -> 0 | J29: ='CRONO SERV'!AB273 -> 0 | K29: ='CRONO SERV'!AC273 -> 0 | L29: ='CRONO SERV'!AD273 -> 0 | M29: ='CRONO SERV'!AE273 -> 0 | N29: =SUM(F29:M29) -> 478942.99
B30: 25 | C30: SS-96/2026 | D30: CFTV U-47 | E30: Elétrica | F30: ='CRONO SERV'!X288 -> 0 | G30: ='CRONO SERV'!Y288 -> 68735.865 | H30: ='CRONO SERV'!Z288 -> 0 | I30: ='CRONO SERV'!AA288 -> 0 | J30: ='CRONO SERV'!AB288 -> 0 | K30: ='CRONO SERV'!AC288 -> 0 | L30: ='CRONO SERV'!AD288 -> 0 | M30: ='CRONO SERV'!AE288 -> 0 | N30: =SUM(F30:M30) -> 68735.865
B31: 26 | C31: SS-96/2025 | D31: IN - 5250-25-010 - Melhoria acesso bloco K 27-TQ-01 C e D - Montagem | E31: Mecânica | F31: ='CRONO SERV'!X292 -> 0 | G31: ='CRONO SERV'!Y292 -> 116485.25 | H31: ='CRONO SERV'!Z292 -> 275195.52 | I31: ='CRONO SERV'!AA292 -> 112286.56 | J31: ='CRONO SERV'!AB292 -> 95380.335 | K31: ='CRONO SERV'!AC292 -> 0 | L31: ='CRONO SERV'!AD292 -> 0 | M31: ='CRONO SERV'!AE292 -> 0 | N31: =SUM(F31:M31) -> 599347.67
B32: 27 | C32: SS-97/2025 | D32: IN - 5250-25-011 - Melhoria acesso bloco P 27-TQ-01 K e M - Montagem | E32: Mecânica | F32: ='CRONO SERV'!X316 -> 0 | G32: ='CRONO SERV'!Y316 -> 24765.26 | H32: ='CRONO SERV'!Z316 -> 134793.79 | I32: ='CRONO SERV'!AA316 -> 459613.19 | J32: ='CRONO SERV'!AB316 -> 383545.18 | K32: ='CRONO SERV'!AC316 -> 0 | L32: ='CRONO SERV'!AD316 -> 0 | M32: ='CRONO SERV'!AE316 -> 0 | N32: =SUM(F32:M32) -> 1002717.4
B33: 28 | C33: SS-98/2025 | D33: IN - 5250-25-011 - Melhoria acesso bloco P 27-TQ-01 K e M - Montagem | E33: Mecânica | F33: ='CRONO SERV'!X340 -> 0 | G33: ='CRONO SERV'!Y340 -> 16780.5 | H33: ='CRONO SERV'!Z340 -> 53447.384 | I33: ='CRONO SERV'!AA340 -> 328544.1 | J33: ='CRONO SERV'!AB340 -> 341309.25 | K33: ='CRONO SERV'!AC340 -> 0 | L33: ='CRONO SERV'!AD340 -> 0 | M33: ='CRONO SERV'!AE340 -> 0 | N33: =SUM(F33:M33) -> 740081.24
B34: 29 | C34: SS-166/2025 | D34: IN - 5250-25-010 - Melhoria acesso bloco K 27-TQ-01 E - Montagem | E34: Mecânica | F34: ='CRONO SERV'!X363 -> 13537.891 | G34: ='CRONO SERV'!Y363 -> 128622.07 | H34: ='CRONO SERV'!Z363 -> 63410.07 | I34: ='CRONO SERV'!AA363 -> 90250.366 | J34: ='CRONO SERV'!AB363 -> 104792.77 | K34: ='CRONO SERV'!AC363 -> 0 | L34: ='CRONO SERV'!AD363 -> 0 | M34: ='CRONO SERV'!AE363 -> 0 | N34: =SUM(F34:M34) -> 400613.17
B35: 30 | C35: SS-100/2025 | D35: IN - 5250-24-051 - Melhoria do Acesso aos TQ´s de Escuros 27-TQ-116-A/B - Montagem | E35: Mecânica | F35: ='CRONO SERV'!X386 -> 4200.906 | G35: ='CRONO SERV'!Y386 -> 128688.32 | H35: ='CRONO SERV'!Z386 -> 148091.72 | I35: ='CRONO SERV'!AA386 -> 19342.555 | J35: ='CRONO SERV'!AB386 -> 0 | K35: ='CRONO SERV'!AC386 -> 0 | L35: ='CRONO SERV'!AD386 -> 0 | M35: ='CRONO SERV'!AE386 -> 0 | N35: =SUM(F35:M35) -> 300323.5
B36: 31 | C36: SS-171/2025 | D36: IN - 5250-24-051 - Melhoria do Acesso aos TQ´s de Escuros 27-TQ-116-D/F - Montagem | E36: Mecânica | F36: ='CRONO SERV'!X407 -> 0 | G36: ='CRONO SERV'!Y407 -> 8229.0379 | H36: ='CRONO SERV'!Z407 -> 96757.408 | I36: ='CRONO SERV'!AA407 -> 188266.34 | J36: ='CRONO SERV'!AB407 -> 14727.931 | K36: ='CRONO SERV'!AC407 -> 0 | L36: ='CRONO SERV'!AD407 -> 0 | M36: ='CRONO SERV'!AE407 -> 0 | N36: =SUM(F36:M36) -> 307980.72
B37: 32 | C37: SS-172/2025 | D37: IN - 5250-24-051 - Melhoria do Acesso aos TQ´s de Escuros 27-TQ-116-D/F - Montagem | E37: Mecânica | F37: ='CRONO SERV'!X429 -> 0 | G37: ='CRONO SERV'!Y429 -> 6398.3081 | H37: ='CRONO SERV'!Z429 -> 72918.187 | I37: ='CRONO SERV'!AA429 -> 220615.3 | J37: ='CRONO SERV'!AB429 -> 26144.015 | K37: ='CRONO SERV'!AC429 -> 19085.006 | L37: ='CRONO SERV'!AD429 -> 0 | M37: ='CRONO SERV'!AE429 -> 0 | N37: =SUM(F37:M37) -> 345160.82
B38: 33 | C38: SS-103/2026 | D38: PMBC MIGRAÇÃO DAS BOMBAS DA U-0047 PARA O SDCD | E38: Elétrica | F38: ='CRONO SERV'!X451 -> 17135.817 | G38: ='CRONO SERV'!Y451 -> 23779.132 | H38: ='CRONO SERV'!Z451 -> 0 | I38: ='CRONO SERV'!AA451 -> 0 | J38: ='CRONO SERV'!AB451 -> 0 | K38: ='CRONO SERV'!AC451 -> 0 | L38: ='CRONO SERV'!AD451 -> 0 | M38: ='CRONO SERV'!AE451 -> 0 | N38: =SUM(F38:M38) -> 40914.949
B39: 34 | C39: SS-109/2026 | D39: IN - 5250-24-085 - Phase-Out do Diesel S500 - Mudança 4.1 - Fabricação (Tubovias) | E39: Mecânica | F39: ='CRONO SERV'!X459 -> 103605.84 | G39: ='CRONO SERV'!Y459 -> 309293.64 | H39: ='CRONO SERV'!Z459 -> 161818.85 | I39: ='CRONO SERV'!AA459 -> 0 | J39: ='CRONO SERV'!AB459 -> 0 | K39: ='CRONO SERV'!AC459 -> 0 | L39: ='CRONO SERV'!AD459 -> 0 | M39: ='CRONO SERV'!AE459 -> 0 | N39: =SUM(F39:M39) -> 574718.32
B40: 35 | C40: SS-110/2026 | D40: IN - 5250-24-085 - Phase-Out do Diesel S500 - Mudança 4.1 - Montagem (Tubovias) | E40: Mecânica | F40: ='CRONO SERV'!X463 -> 153566.31 | G40: ='CRONO SERV'!Y463 -> 429735.64 | H40: ='CRONO SERV'!Z463 -> 447774.83 | I40: ='CRONO SERV'!AA463 -> 117679.34 | J40: ='CRONO SERV'!AB463 -> 0 | K40: ='CRONO SERV'!AC463 -> 18924.675 | L40: ='CRONO SERV'!AD463 -> 0 | M40: ='CRONO SERV'!AE463 -> 0 | N40: =SUM(F40:M40) -> 1167680.8
B41: 36 | C41: SS-123/2026 | D41: IN-5250-23-017 - TERRAPLANAGEM U-623 | E41: Civil | F41: ='CRONO SERV'!X468 -> 0 | G41: ='CRONO SERV'!Y468 -> 354277.69 | H41: ='CRONO SERV'!Z468 -> 0 | I41: ='CRONO SERV'!AA468 -> 0 | J41: ='CRONO SERV'!AB468 -> 0 | K41: ='CRONO SERV'!AC468 -> 0 | L41: ='CRONO SERV'!AD468 -> 0 | M41: ='CRONO SERV'!AE468 -> 0 | N41: =SUM(F41:M41) -> 354277.69
B42: 37 | C42: SS-125/2026 | D42: U-110 - DEMOLIÇÃO FUNDAÇÃO - 110-R-01 | E42: Civil | F42: ='CRONO SERV'!X473 -> 4245.9956 | G42: ='CRONO SERV'!Y473 -> 0 | H42: ='CRONO SERV'!Z473 -> 0 | I42: ='CRONO SERV'!AA473 -> 0 | J42: ='CRONO SERV'!AB473 -> 0 | K42: ='CRONO SERV'!AC473 -> 0 | L42: ='CRONO SERV'!AD473 -> 0 | M42: ='CRONO SERV'!AE473 -> 0 | N42: =SUM(F42:M42) -> 4245.9956
B43: 38 | C43: SS-126/2026 | D43: U-110 - CONSTRUÇÃO FUNDAÇÃO - 110-R-01 | E43: Civil | F43: ='CRONO SERV'!X477 -> 125265.09 | G43: ='CRONO SERV'!Y477 -> 67761.412 | H43: ='CRONO SERV'!Z477 -> 89289.226 | I43: ='CRONO SERV'!AA477 -> 0 | J43: ='CRONO SERV'!AB477 -> 0 | K43: ='CRONO SERV'!AC477 -> 0 | L43: ='CRONO SERV'!AD477 -> 0 | M43: ='CRONO SERV'!AE477 -> 0 | N43: =SUM(F43:M43) -> 282315.73
...

Sheet CRONO SERV
K2: FISICO_QUANTIDADES | V2: FINANCEIRO_VALOR (R$)
K3: Medido | L3: Saldo | M3: 46143 | N3: 46174 | O3: 46204 | P3: 46235 | Q3: 46266 | R3: 46296 | S3: 46327 | T3: 46357 | V3: Acum | W3: Saldo | X3: 46143 | Y3: 46174 | Z3: 46204 | AA3: 46235 | AB3: 46266 | AC3: 46296 | AD3: 46327 | AE3: 46357 | AF3: TOTAL MAIO A DEZ/2026 | AH3: CONF.FIS | AI3: CONF.R$
B4: SS | C4: DESCRIÇÃO-SS | D4: ITEM | E4: DESCRIÇÃO-ITEM | F4: UN | G4: Qtd | H4: PREÇO UNITÁRIO (R$) | I4: PREÇO TOTAL (R$)
V6: =SUM(V7,V12,V24,V31,V37,V39,V43,V47,V71,V89,V121,V136,V138,V156,V162,V171,V181,V190,V208,V238,V247,V250,V264,V273,V288,V292,V316,V340,V363,V386,V407,V429,V451,V459,V463,V468,V473,V477,V495,V498,V503,V534,V539,V549,V564,V577,V580,V583,V621,V633,V636,V647,V663,V679,V718,V724,V730,V736) -> 13013393 | W6: =SUM(W7,W12,W24,W31,W37,W39,W43,W47,W71,W89,W121,W136,W138,W156,W162,W171,W181,W190,W208,W238,W247,W250,W264,W273,W288,W292,W316,W340,W363,W386,W407,W429,W451,W459,W463,W468,W473,W477,W495,W498,W503,W534,W539,W549,W564,W577,W580,W583,W621,W633,W636,W647,W663,W679,W718,W724,W730,W736) -> 28192829 | X6: =SUM(X7,X12,X24,X31,X37,X39,X43,X47,X71,X89,X121,X136,X138,X156,X162,X171,X181,X190,X208,X238,X247,X250,X264,X273,X288,X292,X316,X340,X363,X386,X407,X429,X451,X459,X463,X468,X473,X477,X495,X498,X503,X534,X539,X549,X564,X577,X580,X583,X621,X633,X636,X647,X663,X679,X718,X724,X730,X736) -> 3469594.7 | Y6: =SUM(Y7,Y12,Y24,Y31,Y37,Y39,Y43,Y47,Y71,Y89,Y121,Y136,Y138,Y156,Y162,Y171,Y181,Y190,Y208,Y238,Y247,Y250,Y264,Y273,Y288,Y292,Y316,Y340,Y363,Y386,Y407,Y429,Y451,Y459,Y463,Y468,Y473,Y477,Y495,Y498,Y503,Y534,Y539,Y549,Y564,Y577,Y580,Y583,Y621,Y633,Y636,Y647,Y663,Y679,Y718,Y724,Y730,Y736) -> 7129677.9 | Z6: =SUM(Z7,Z12,Z24,Z31,Z37,Z39,Z43,Z47,Z71,Z89,Z121,Z136,Z138,Z156,Z162,Z171,Z181,Z190,Z208,Z238,Z247,Z250,Z264,Z273,Z288,Z292,Z316,Z340,Z363,Z386,Z407,Z429,Z451,Z459,Z463,Z468,Z473,Z477,Z495,Z498,Z503,Z534,Z539,Z549,Z564,Z577,Z580,Z583,Z621,Z633,Z636,Z647,Z663,Z679,Z718,Z724,Z730,Z736) -> 7604774.5 | AA6: =SUM(AA7,AA12,AA24,AA31,AA37,AA39,AA43,AA47,AA71,AA89,AA121,AA136,AA138,AA156,AA162,AA171,AA181,AA190,AA208,AA238,AA247,AA250,AA264,AA273,AA288,AA292,AA316,AA340,AA363,AA386,AA407,AA429,AA451,AA459,AA463,AA468,AA473,AA477,AA495,AA498,AA503,AA534,AA539,AA549,AA564,AA577,AA580,AA583,AA621,AA633,AA636,AA647,AA663,AA679,AA718,AA724,AA730,AA736) -> 4299492.3 | AB6: =SUM(AB7,AB12,AB24,AB31,AB37,AB39,AB43,AB47,AB71,AB89,AB121,AB136,AB138,AB156,AB162,AB171,AB181,AB190,AB208,AB238,AB247,AB250,AB264,AB273,AB288,AB292,AB316,AB340,AB363,AB386,AB407,AB429,AB451,AB459,AB463,AB468,AB473,AB477,AB495,AB498,AB503,AB534,AB539,AB549,AB564,AB577,AB580,AB583,AB621,AB633,AB636,AB647,AB663,AB679,AB718,AB724,AB730,AB736) -> 2224929.3 | AC6: =SUM(AC7,AC12,AC24,AC31,AC37,AC39,AC43,AC47,AC71,AC89,AC121,AC136,AC138,AC156,AC162,AC171,AC181,AC190,AC208,AC238,AC247,AC250,AC264,AC273,AC288,AC292,AC316,AC340,AC363,AC386,AC407,AC429,AC451,AC459,AC463,AC468,AC473,AC477,AC495,AC498,AC503,AC534,AC539,AC549,AC564,AC577,AC580,AC583,AC621,AC633,AC636,AC647,AC663,AC679,AC718,AC724,AC730,AC736) -> 935454.48 | ... AF6: =SUM(AF7,AF12,AF24,AF31,AF37,AF39,AF43,AF47,AF71,AF89,AF121,AF136,AF138,AF156,AF162,AF171,AF181,AF190,AF208,AF238,AF247,AF250,AF264,AF273,AF288,AF292,AF316,AF340,AF363,AF386,AF407,AF429,AF451,AF459,AF463,AF468,AF473,AF477,AF495,AF498,AF503,AF534,AF539,AF549,AF564,AF577,AF580,AF583,AF621,AF633,AF636,AF647,AF663,AF679,AF718,AF724,AF730,AF736) -> 26201481
B7: SS-1/2026 | C7: Adequação Escadas de Marinheiro - Execução - UN 01,102,108,109,209 - UDAV 01/02 | I7: =SUM(I8:I11) -> 173199.53 | V7: =SUM(V8:V11) -> 38762.624 | W7: =SUM(W8:W11) -> 134436.9 | X7: =SUM(X8:X11) -> 8448.9511 | Y7: =SUM(Y8:Y11) -> 22525.794 | Z7: =SUM(Z8:Z11) -> 22525.794 | AA7: =SUM(AA8:AA11) -> 27860.851 | AB7: =SUM(AB8:AB11) -> 26675.282 | AC7: =SUM(AC8:AC11) -> 26400.231 | ... AF7: =SUM(AF8:AF11) -> 134436.9
B8: SS-1/2026 | C8: Adequação Escadas de Marinheiro - Execução - UN 01,102,108,109,209 | D8: 1.2.22.1 | E8: Fabricação de estrutura | F8: kg | G8: 796.438 | H8: 34.841778 | I8: =H8*G8 -> 27749.316 | K8: 653.908 | L8: =G8-K8 -> 142.53 | M8: =L8 -> 142.53 | V8: =$H8*K8 -> 22783.317 | W8: =$H8*L8 -> 4965.9986 | X8: =$H8*M8 -> 4965.9986 | Y8: =$H8*N8 -> 0 | Z8: =$H8*O8 -> 0 | AA8: =$H8*P8 -> 0 | AB8: =$H8*Q8 -> 0 | AC8: =$H8*R8 -> 0 | ... AE8: =$H8*T8 -> 0 | AF8: =SUM(X8:AE8) -> 4965.9986 | AH8: =L8-SUM(M8:T8) -> 0 | AI8: =W8-SUM(X8:AE8) -> 0
B9: SS-1/2026 | C9: Adequação Escadas de Marinheiro - Execução - UN 01,102,108,109,209 | D9: 1.2.23.1 | E9: Serviço de montagem de estrutura | F9: kg | G9: 796.438 | H9: 24.436627 | I9: =H9*G9 -> 19462.259 | K9: 653.908 | L9: =G9-K9 -> 142.53 | M9: =L9 -> 142.53 | V9: =$H9*K9 -> 15979.306 | W9: =$H9*L9 -> 3482.9525 | X9: =$H9*M9 -> 3482.9525 | Y9: =$H9*N9 -> 0 | Z9: =$H9*O9 -> 0 | AA9: =$H9*P9 -> 0 | AB9: =$H9*Q9 -> 0 | AC9: =$H9*R9 -> 0 | ... AE9: =$H9*T9 -> 0 | AF9: =SUM(X9:AE9) -> 3482.9525 | AH9: =L9-SUM(M9:T9) -> 0 | AI9: =W9-SUM(X9:AE9) -> 0
B10: SS-8/2026 | C10: Adequação Escadas de Marinheiro - Execução - UDAV 01/02 | D10: 1.2.22.1 | E10: Fabricação de estrutura | F10: kg | G10: 2125.36 | H10: 34.841778 | I10: =H10*G10 -> 74051.322 | L10: =G10-K10 -> 2125.36 | N10: 380 | O10: 380 | P10: 470 | Q10: 450 | R10: =L10-N10-O10-P10-Q10 -> 445.36 | V10: =$H10*K10 -> 0 | W10: =$H10*L10 -> 74051.322 | X10: =$H10*M10 -> 0 | Y10: =$H10*N10 -> 13239.876 | Z10: =$H10*O10 -> 13239.876 | AA10: =$H10*P10 -> 16375.636 | AB10: =$H10*Q10 -> 15678.8 | AC10: =$H10*R10 -> 15517.134 | ... AE10: =$H10*T10 -> 0 | AF10: =SUM(X10:AE10) -> 74051.322 | AH10: =L10-SUM(M10:T10) -> 0 | AI10: =W10-SUM(X10:AE10) -> 0
B11: SS-8/2026 | C11: Adequação Escadas de Marinheiro - Execução - UDAV 01/02 | D11: 1.2.23.1 | E11: Serviço de montagem de estrutura | F11: kg | G11: 2125.36 | H11: 24.436627 | I11: =H11*G11 -> 51936.63 | L11: =G11-K11 -> 2125.36 | N11: 380 | O11: 380 | P11: 470 | Q11: 450 | R11: =L11-N11-O11-P11-Q11 -> 445.36 | V11: =$H11*K11 -> 0 | W11: =$H11*L11 -> 51936.63 | X11: =$H11*M11 -> 0 | Y11: =$H11*N11 -> 9285.9183 | Z11: =$H11*O11 -> 9285.9183 | AA11: =$H11*P11 -> 11485.215 | AB11: =$H11*Q11 -> 10996.482 | AC11: =$H11*R11 -> 10883.096 | ... AE11: =$H11*T11 -> 0 | AF11: =SUM(X11:AE11) -> 51936.63 | AH11: =L11-SUM(M11:T11) -> 0 | AI11: =W11-SUM(X11:AE11) -> 0
B12: SS-2/2026 | C12: IN-5250-24-092 - PT-200 - Escavação Manual para Pré Furos e Fundação | I12: =SUM(I13:I23) -> 266884.66 | V12: =SUM(V13:V23) -> 82951.949 | W12: =SUM(W13:W23) -> 182638.26 | X12: =SUM(X13:X23) -> 86040.747 | Y12: =SUM(Y13:Y23) -> 47782.443 | Z12: =SUM(Z13:Z23) -> 0 | AA12: =SUM(AA13:AA23) -> 0 | AB12: =SUM(AB13:AB23) -> 0 | AC12: =SUM(AC13:AC23) -> 0 | ... AF12: =SUM(AF13:AF23) -> 133823.19
B13: SS-2/2026 | C13: IN-5250-24-092 - PT-200 - Escavação Manual para Pré Furos e Fundação | D13: 1.1.1.2 | E13: Demolição de concreto simples, armado ou refratários | F13: m³ | G13: 36.18 | H13: 584.29184 | I13: =H13*G13 -> 21139.679 | K13: 5.929 | L13: =G13-K13 -> 30.251 | M13: =L13 -> 30.251 | V13: =$H13*K13 -> 3464.2663 | W13: =$H13*L13 -> 17675.412 | X13: =$H13*M13 -> 17675.412 | Y13: =$H13*N13 -> 0 | Z13: =$H13*O13 -> 0 | AA13: =$H13*P13 -> 0 | AB13: =$H13*Q13 -> 0 | AC13: =$H13*R13 -> 0 | ... AE13: =$H13*T13 -> 0 | AF13: =SUM(X13:AE13) -> 17675.412 | AH13: =L13-SUM(M13:T13) -> 0 | AI13: =W13-SUM(X13:AE13) -> 0
B14: SS-2/2026 | C14: IN-5250-24-092 - PT-200 - Escavação Manual para Pré Furos e Fundação | D14: 1.1.1.3 | E14: Demolição controlada de concreto | F14: m³ | G14: 52.26 | H14: 973.81973 | I14: =H14*G14 -> 50891.819 | L14: =G14-K14 -> 52.26 | M14: =L14 -> 52.26 | V14: =$H14*K14 -> 0 | W14: =$H14*L14 -> 50891.819 | X14: =$H14*M14 -> 50891.819 | Y14: =$H14*N14 -> 0 | Z14: =$H14*O14 -> 0 | AA14: =$H14*P14 -> 0 | AB14: =$H14*Q14 -> 0 | AC14: =$H14*R14 -> 0 | ... AE14: =$H14*T14 -> 0 | AF14: =SUM(X14:AE14) -> 50891.819 | AH14: =L14-SUM(M14:T14) -> 0 | AI14: =W14-SUM(X14:AE14) -> 0
B15: SS-2/2026 | C15: IN-5250-24-092 - PT-200 - Escavação Manual para Pré Furos e Fundação | D15: 1.1.1.5 | E15: Apicoamento de concreto | F15: m² | G15: 20.1 | H15: 54.601315 | I15: =H15*G15 -> 1097.4864 | L15: =G15-K15 -> 20.1 | M15: =L15 -> 20.1 | V15: =$H15*K15 -> 0 | W15: =$H15*L15 -> 1097.4864 | X15: =$H15*M15 -> 1097.4864 | Y15: =$H15*N15 -> 0 | Z15: =$H15*O15 -> 0 | AA15: =$H15*P15 -> 0 | AB15: =$H15*Q15 -> 0 | AC15: =$H15*R15 -> 0 | ... AE15: =$H15*T15 -> 0 | AF15: =SUM(X15:AE15) -> 1097.4864 | AH15: =L15-SUM(M15:T15) -> 0 | AI15: =W15-SUM(X15:AE15) -> 0
B16: SS-2/2026 | C16: IN-5250-24-092 - PT-200 - Escavação Manual para Pré Furos e Fundação | D16: 1.1.1.6 | E16: Escarificação de concreto | F16: m² | G16: 18.425 | H16: 136.52157 | I16: =H16*G16 -> 2515.41 | L16: =G16-K16 -> 18.425 | M16: =L16 -> 18.425 | V16: =$H16*K16 -> 0 | W16: =$H16*L16 -> 2515.41 | X16: =$H16*M16 -> 2515.41 | Y16: =$H16*N16 -> 0 | Z16: =$H16*O16 -> 0 | AA16: =$H16*P16 -> 0 | AB16: =$H16*Q16 -> 0 | AC16: =$H16*R16 -> 0 | ... AE16: =$H16*T16 -> 0 | AF16: =SUM(X16:AE16) -> 2515.41 | AH16: =L16-SUM(M16:T16) -> 0 | AI16: =W16-SUM(X16:AE16) -> 0
B17: SS-2/2026 | C17: IN-5250-24-092 - PT-200 - Escavação Manual para Pré Furos e Fundação | D17: 1.1.1.16 | E17: Levantamento topográfico | F17: Hs | G17: 32 | H17: 231.15275 | I17: =H17*G17 -> 7396.888 | K17: 26.4 | V17: =$H17*K17 -> 6102.4326 | W17: =$H17*L17 -> 0 | X17: =$H17*M17 -> 0 | Y17: =$H17*N17 -> 0 | Z17: =$H17*O17 -> 0 | AA17: =$H17*P17 -> 0 | AB17: =$H17*Q17 -> 0 | AC17: =$H17*R17 -> 0 | ... AE17: =$H17*T17 -> 0 | AF17: =SUM(X17:AE17) -> 0 | AH17: =L17-SUM(M17:T17) -> 0 | AI17: =W17-SUM(X17:AE17) -> 0
B18: SS-2/2026 | C18: IN-5250-24-092 - PT-200 - Escavação Manual para Pré Furos e Fundação | D18: 1.1.2.1 | E18: Escavação manual em solo | F18: m³ | G18: 93.8 | H18: 199.78886 | I18: =H18*G18 -> 18740.195 | K18: 41.29 | L18: =G18-K18 -> 52.51 | M18: =L18 -> 52.51 | V18: =$H18*K18 -> 8249.2819 | W18: =$H18*L18 -> 10490.913 | X18: =$H18*M18 -> 10490.913 | Y18: =$H18*N18 -> 0 | Z18: =$H18*O18 -> 0 | AA18: =$H18*P18 -> 0 | AB18: =$H18*Q18 -> 0 | AC18: =$H18*R18 -> 0 | ... AE18: =$H18*T18 -> 0 | AF18: =SUM(X18:AE18) -> 10490.913 | AH18: =L18-SUM(M18:T18) -> 0 | AI18: =W18-SUM(X18:AE18) -> 0
B19: SS-2/2026 | C19: IN-5250-24-092 - PT-200 - Escavação Manual para Pré Furos e Fundação | D19: 1.1.2.2 | E19: Escavação mecanizada em solo até 3m | F19: m³ | G19: 76.38 | H19: 44.117647 | I19: =H19*G19 -> 3369.7059 | L19: =G19-K19 -> 76.38 | M19: =L19 -> 76.38 | V19: =$H19*K19 -> 0 | W19: =$H19*L19 -> 3369.7059 | X19: =$H19*M19 -> 3369.7059 | Y19: =$H19*N19 -> 0 | Z19: =$H19*O19 -> 0 | AA19: =$H19*P19 -> 0 | AB19: =$H19*Q19 -> 0 | AC19: =$H19*R19 -> 0 | ... AE19: =$H19*T19 -> 0 | AF19: =SUM(X19:AE19) -> 3369.7059 | AH19: =L19-SUM(M19:T19) -> 0 | AI19: =W19-SUM(X19:AE19) -> 0
B20: SS-2/2026 | C20: IN-5250-24-092 - PT-200 - Escavação Manual para Pré Furos e Fundação | D20: 1.1.2.4 | E20: Escoramento de escavações | F20: m² | G20: 48.24 | H20: 221.1847 | I20: =H20*G20 -> 10669.95 | L20: =G20-K20 -> 48.24 | N20: =L20 -> 48.24 | V20: =$H20*K20 -> 0 | W20: =$H20*L20 -> 10669.95 | X20: =$H20*M20 -> 0 | Y20: =$H20*N20 -> 10669.95 | Z20: =$H20*O20 -> 0 | AA20: =$H20*P20 -> 0 | AB20: =$H20*Q20 -> 0 | AC20: =$H20*R20 -> 0 | ... AE20: =$H20*T20 -> 0 | AF20: =SUM(X20:AE20) -> 10669.95 | AH20: =L20-SUM(M20:T20) -> 0 | AI20: =W20-SUM(X20:AE20) -> 0
B21: SS-2/2026 | C21: IN-5250-24-092 - PT-200 - Escavação Manual para Pré Furos e Fundação | D21: 1.1.2.12 | E21: Transporte de material escavado, incluindo carga e descarga e espalhamento | F21: m³ | G21: 96.48 | H21: 90.646229 | I21: =H21*G21 -> 8745.5482 | K21: 41.29 | L21: =G21-K21 -> 55.19 | N21: =L21 -> 55.19 | V21: =$H21*K21 -> 3742.7828 | W21: =$H21*L21 -> 5002.7654 | X21: =$H21*M21 -> 0 | Y21: =$H21*N21 -> 5002.7654 | Z21: =$H21*O21 -> 0 | AA21: =$H21*P21 -> 0 | AB21: =$H21*Q21 -> 0 | AC21: =$H21*R21 -> 0 | ... AE21: =$H21*T21 -> 0 | AF21: =SUM(X21:AE21) -> 5002.7654 | AH21: =L21-SUM(M21:T21) -> 0 | AI21: =W21-SUM(X21:AE21) -> 0
B22: SS-2/2026 | C22: IN-5250-24-092 - PT-200 - Escavação Manual para Pré Furos e Fundação | D22: 1.2.7.1 | E22: Desmontagem e remoção | F22: kg | G22: 2000 | H22: 46.722364 | I22: =H22*G22 -> 93444.727 | K22: =G22-686 -> 1314 | L22: =G22-K22 -> 686 | V22: =$H22*K22 -> 61393.186 | W22: =$H22*L22 -> 32051.541 | X22: =$H22*M22 -> 0 | Y22: =$H22*N22 -> 0 | Z22: =$H22*O22 -> 0 | AA22: =$H22*P22 -> 0 | AB22: =$H22*Q22 -> 0 | AC22: =$H22*R22 -> 0 | ... AE22: =$H22*T22 -> 0 | AF22: =SUM(X22:AE22) -> 0 | AH22: =L22-SUM(M22:T22) -> 686 | AI22: =W22-SUM(X22:AE22) -> 32051.541
B23: SS-2/2026 | C23: IN-5250-24-092 - PT-200 - Escavação Manual para Pré Furos e Fundação | D23: 1.2.23.1 | E23: Serviço de montagem de estrutura | F23: kg | G23: 2000 | H23: 24.436627 | I23: =H23*G23 -> 48873.254 | L23: =G23-K23 -> 2000 | N23: =1314 -> 1314 | V23: =$H23*K23 -> 0 | W23: =$H23*L23 -> 48873.254 | X23: =$H23*M23 -> 0 | Y23: =$H23*N23 -> 32109.728 | Z23: =$H23*O23 -> 0 | AA23: =$H23*P23 -> 0 | AB23: =$H23*Q23 -> 0 | AC23: =$H23*R23 -> 0 | ... AE23: =$H23*T23 -> 0 | AF23: =SUM(X23:AE23) -> 32109.728 | AH23: =L23-SUM(M23:T23) -> 686 | AI23: =W23-SUM(X23:AE23) -> 16763.526
B24: SS-14/2026 | C24: PMBC - 5250-26-100 - ALTERAÇÕES - HAZOP DA U-001 E U-101 | I24: =SUM(I25:I30) -> 19165.032 | V24: =SUM(V25:V30) -> 0 | W24: =SUM(W25:W30) -> 19165.032 | X24: =SUM(X25:X30) -> 7793.8298 | Y24: =SUM(Y25:Y30) -> 11371.202 | Z24: =SUM(Z25:Z30) -> 0 | AA24: =SUM(AA25:AA30) -> 0 | AB24: =SUM(AB25:AB30) -> 0 | AC24: =SUM(AC25:AC30) -> 0 | ... AF24: =SUM(AF25:AF30) -> 19165.032
B25: SS-14/2026 | C25: PMBC - 5250-26-100 - ALTERAÇÕES - HAZOP DA U-001 E U-101 | D25: 1.2.1.1 | E25: Tubulações (inclui suportes de tubulação) - Diâmetro menor ou igual a 1.1/2" | F25: kg | G25: 42.77996 | H25: 48.374646 | I25: =H25*G25 -> 2069.4654 | L25: =G25-K25 -> 42.77996 | M25: =G25 -> 42.77996 | V25: =$H25*K25 -> 0 | W25: =$H25*L25 -> 2069.4654 | X25: =$H25*M25 -> 2069.4654 | Y25: =$H25*N25 -> 0 | Z25: =$H25*O25 -> 0 | AA25: =$H25*P25 -> 0 | AB25: =$H25*Q25 -> 0 | AC25: =$H25*R25 -> 0 | ... AE25: =$H25*T25 -> 0 | AF25: =SUM(X25:AE25) -> 2069.4654 | AH25: =L25-SUM(M25:T25) -> 0 | AI25: =W25-SUM(X25:AE25) -> 0
B26: SS-14/2026 | C26: PMBC - 5250-26-100 - ALTERAÇÕES - HAZOP DA U-001 E U-101 | D26: 1.2.2.1 | E26: Tubulações (inclui suportes de tubulação) - Diâmetro menor ou igual a 1.1/2" | F26: kg | G26: 71.25858 | H26: 80.332283 | I26: =H26*G26 -> 5724.3644 | L26: =G26-K26 -> 71.25858 | M26: =G26 -> 71.25858 | V26: =$H26*K26 -> 0 | W26: =$H26*L26 -> 5724.3644 | X26: =$H26*M26 -> 5724.3644 | Y26: =$H26*N26 -> 0 | Z26: =$H26*O26 -> 0 | AA26: =$H26*P26 -> 0 | AB26: =$H26*Q26 -> 0 | AC26: =$H26*R26 -> 0 | ... AE26: =$H26*T26 -> 0 | AF26: =SUM(X26:AE26) -> 5724.3644 | AH26: =L26-SUM(M26:T26) -> 0 | AI26: =W26-SUM(X26:AE26) -> 0
B27: SS-14/2026 | C27: PMBC - 5250-26-100 - ALTERAÇÕES - HAZOP DA U-001 E U-101 | D27: 1.2.6.1 | E27: Montagem ou desmontagem - Diâmetro menor ou igual a 4" | F27: m | G27: 9 | H27: 615.87081 | I27: =H27*G27 -> 5542.8373 | L27: =G27-K27 -> 9 | N27: =G27 -> 9 | V27: =$H27*K27 -> 0 | W27: =$H27*L27 -> 5542.8373 | X27: =$H27*M27 -> 0 | Y27: =$H27*N27 -> 5542.8373 | Z27: =$H27*O27 -> 0 | AA27: =$H27*P27 -> 0 | AB27: =$H27*Q27 -> 0 | AC27: =$H27*R27 -> 0 | ... AE27: =$H27*T27 -> 0 | AF27: =SUM(X27:AE27) -> 5542.8373 | AH27: =L27-SUM(M27:T27) -> 0 | AI27: =W27-SUM(X27:AE27) -> 0
B28: SS-14/2026 | C28: PMBC - 5250-26-100 - ALTERAÇÕES - HAZOP DA U-001 E U-101 | D28: 1.2.7.1 | E28: Desmontagem e remoção | F28: kg | G28: 41.3194 | H28: 46.722364 | I28: =H28*G28 -> 1930.54 | L28: =G28-K28 -> 41.3194 | N28: =G28 -> 41.3194 | V28: =$H28*K28 -> 0 | W28: =$H28*L28 -> 1930.54 | X28: =$H28*M28 -> 0 | Y28: =$H28*N28 -> 1930.54 | Z28: =$H28*O28 -> 0 | AA28: =$H28*P28 -> 0 | AB28: =$H28*Q28 -> 0 | AC28: =$H28*R28 -> 0 | ... AE28: =$H28*T28 -> 0 | AF28: =SUM(X28:AE28) -> 1930.54 | AH28: =L28-SUM(M28:T28) -> 0 | AI28: =W28-SUM(X28:AE28) -> 0
B29: SS-14/2026 | C29: PMBC - 5250-26-100 - ALTERAÇÕES - HAZOP DA U-001 E U-101 | D29: 1.4.1.4 | E29: Desligamento e remoção de manômetro, termômetro, termopar ou termoresistência | F29: un | G29: 4 | H29: 159.922 | I29: =H29*G29 -> 639.68799 | L29: =G29-K29 -> 4 | N29: =G29 -> 4 | V29: =$H29*K29 -> 0 | W29: =$H29*L29 -> 639.68799 | X29: =$H29*M29 -> 0 | Y29: =$H29*N29 -> 639.68799 | Z29: =$H29*O29 -> 0 | AA29: =$H29*P29 -> 0 | AB29: =$H29*Q29 -> 0 | AC29: =$H29*R29 -> 0 | ... AE29: =$H29*T29 -> 0 | AF29: =SUM(X29:AE29) -> 639.68799 | AH29: =L29-SUM(M29:T29) -> 0 | AI29: =W29-SUM(X29:AE29) -> 0
B30: SS-14/2026 | C30: PMBC - 5250-26-100 - ALTERAÇÕES - HAZOP DA U-001 E U-101 | D30: 1.4.11.1 | E30: Instalação de manômetro ou termômetro bimetálico | F30: un | G30: 4 | H30: 814.53425 | I30: =H30*G30 -> 3258.137 | L30: =G30-K30 -> 4 | N30: =G30 -> 4 | V30: =$H30*K30 -> 0 | W30: =$H30*L30 -> 3258.137 | X30: =$H30*M30 -> 0 | Y30: =$H30*N30 -> 3258.137 | Z30: =$H30*O30 -> 0 | AA30: =$H30*P30 -> 0 | AB30: =$H30*Q30 -> 0 | AC30: =$H30*R30 -> 0 | ... AE30: =$H30*T30 -> 0 | AF30: =SUM(X30:AE30) -> 3258.137 | AH30: =L30-SUM(M30:T30) -> 0 | AI30: =W30-SUM(X30:AE30) -> 0
B31: SS-36/2026 | C31: Manutenção Civil - Linha do Flare na Av. 8 | I31: =SUM(I32:I36) -> 577840.44 | V31: =SUM(V32:V36) -> 296835.02 | W31: =SUM(W32:W36) -> 281005.42 | X31: =SUM(X32:X36) -> 117974.19 | Y31: =SUM(Y32:Y36) -> 73101.436 | Z31: =SUM(Z32:Z36) -> 89929.793 | AA31: =SUM(AA32:AA36) -> 0 | AB31: =SUM(AB32:AB36) -> 0 | AC31: =SUM(AC32:AC36) -> 0 | ... AF31: =SUM(AF32:AF36) -> 281005.42
B32: SS-36/2026 | C32: Manutenção Civil - Linha do Flare na Av. 8 | D32: 1.1.1.5 | E32: Apicoamento de concreto | F32: m² | G32: 204.312 | H32: 54.601315 | I32: =H32*G32 -> 11155.704 | K32: 6.323 | L32: =G32-K32 -> 197.989 | M32: =SUMIF(MC_SS_36!$A:$A,'CRONO SERV'!$D32,MC_SS_36!E:E) -> 3 | N32: =SUMIF(MC_SS_36!$A:$A,'CRONO SERV'!$D32,MC_SS_36!F:F) -> 87.11516 | O32: =SUMIF(MC_SS_36!$A:$A,'CRONO SERV'!$D32,MC_SS_36!G:G) -> 107.87384 | V32: =$H32*K32 -> 345.24412 | W32: =$H32*L32 -> 10810.46 | X32: =$H32*M32 -> 163.80395 | Y32: =$H32*N32 -> 4756.6023 | Z32: =$H32*O32 -> 5890.0536 | AA32: =$H32*P32 -> 0 | AB32: =$H32*Q32 -> 0 | AC32: =$H32*R32 -> 0 | ... AE32: =$H32*T32 -> 0 | AF32: =SUM(X32:AE32) -> 10810.46 | AH32: =L32-SUM(M32:T32) -> 0 | AI32: =W32-SUM(X32:AE32) -> 0
B33: SS-36/2026 | C33: Manutenção Civil - Linha do Flare na Av. 8 | D33: 1.1.2.14 | E33: Fornecimento, compactação e espalhamento de brita ou bica corrida | F33: m³ | G33: 20 | H33: 217.63088 | I33: =H33*G33 -> 4352.6176 | K33: 17.807 | L33: =G33-K33 -> 2.193 | M33: =SUMIF(MC_SS_36!$A:$A,'CRONO SERV'!$D33,MC_SS_36!E:E) -> 0 | N33: =SUMIF(MC_SS_36!$A:$A,'CRONO SERV'!$D33,MC_SS_36!F:F) -> 2.193 | O33: =SUMIF(MC_SS_36!$A:$A,'CRONO SERV'!$D33,MC_SS_36!G:G) -> 0 | V33: =$H33*K33 -> 3875.3531 | W33: =$H33*L33 -> 477.26452 | X33: =$H33*M33 -> 0 | Y33: =$H33*N33 -> 477.26452 | Z33: =$H33*O33 -> 0 | AA33: =$H33*P33 -> 0 | AB33: =$H33*Q33 -> 0 | AC33: =$H33*R33 -> 0 | ... AE33: =$H33*T33 -> 0 | AF33: =SUM(X33:AE33) -> 477.26452 | AH33: =L33-SUM(M33:T33) -> 0 | AI33: =W33-SUM(X33:AE33) -> 0
B34: SS-36/2026 | C34: Manutenção Civil - Linha do Flare na Av. 8 | D34: 1.1.10.12 | E34: Impermeabilização por cristalização | F34: m² | G34: 681.04 | H34: 196.60862 | I34: =H34*G34 -> 133898.34 | K34: 455.468 | L34: =G34-K34 -> 225.572 | M34: =SUMIF(MC_SS_36!$A:$A,'CRONO SERV'!$D34,MC_SS_36!E:E) -> 225.572 | N34: =SUMIF(MC_SS_36!$A:$A,'CRONO SERV'!$D34,MC_SS_36!F:F) -> 0 | O34: =SUMIF(MC_SS_36!$A:$A,'CRONO SERV'!$D34,MC_SS_36!G:G) -> 0 | V34: =$H34*K34 -> 89548.935 | W34: =$H34*L34 -> 44349.4 | X34: =$H34*M34 -> 44349.4 | Y34: =$H34*N34 -> 0 | Z34: =$H34*O34 -> 0 | AA34: =$H34*P34 -> 0 | AB34: =$H34*Q34 -> 0 | AC34: =$H34*R34 -> 0 | ... AE34: =$H34*T34 -> 0 | AF34: =SUM(X34:AE34) -> 44349.4 | AH34: =L34-SUM(M34:T34) -> 0 | AI34: =W34-SUM(X34:AE34) -> 0
B35: SS-36/2026 | C35: Manutenção Civil - Linha do Flare na Av. 8 | D35: 1.1.15.9 | E35: Reparos rasos (espessuras até 25 mm) | F35: m² | G35: 476.728 | H35: 564.81544 | I35: =H35*G35 -> 269263.34 | K35: 350.804 | L35: =G35-K35 -> 125.924 | M35: =SUMIF(MC_SS_36!$A:$A,'CRONO SERV'!$D35,MC_SS_36!E:E) -> 125.924 | N35: =SUMIF(MC_SS_36!$A:$A,'CRONO SERV'!$D35,MC_SS_36!F:F) -> 0 | O35: =SUMIF(MC_SS_36!$A:$A,'CRONO SERV'!$D35,MC_SS_36!G:G) -> 0 | V35: =$H35*K35 -> 198139.52 | W35: =$H35*L35 -> 71123.82 | X35: =$H35*M35 -> 71123.82 | Y35: =$H35*N35 -> 0 | Z35: =$H35*O35 -> 0 | AA35: =$H35*P35 -> 0 | AB35: =$H35*Q35 -> 0 | AC35: =$H35*R35 -> 0 | ... AE35: =$H35*T35 -> 0 | AF35: =SUM(X35:AE35) -> 71123.82 | AH35: =L35-SUM(M35:T35) -> 0 | AI35: =W35-SUM(X35:AE35) -> 0
B36: SS-36/2026 | C36: Manutenção Civil - Linha do Flare na Av. 8 | D36: 1.1.15.10 | E36: Reparos semi-profundos (espessuras entre 25 mm e 60 mm) | F36: m² | G36: 204.312 | H36: 779.05578 | I36: =H36*G36 -> 159170.45 | K36: 6.323 | L36: =G36-K36 -> 197.989 | M36: =SUMIF(MC_SS_36!$A:$A,'CRONO SERV'!$D36,MC_SS_36!E:E) -> 3 | N36: =SUMIF(MC_SS_36!$A:$A,'CRONO SERV'!$D36,MC_SS_36!F:F) -> 87.11516 | O36: =SUMIF(MC_SS_36!$A:$A,'CRONO SERV'!$D36,MC_SS_36!G:G) -> 107.87384 | V36: =$H36*K36 -> 4925.9697 | W36: =$H36*L36 -> 154244.48 | X36: =$H36*M36 -> 2337.1674 | Y36: =$H36*N36 -> 67867.569 | Z36: =$H36*O36 -> 84039.739 | AA36: =$H36*P36 -> 0 | AB36: =$H36*Q36 -> 0 | AC36: =$H36*R36 -> 0 | ... AE36: =$H36*T36 -> 0 | AF36: =SUM(X36:AE36) -> 154244.48 | AH36: =L36-SUM(M36:T36) -> 0 | AI36: =W36-SUM(X36:AE36) -> 0
B37: SS-39/2026 | C37: IN-5250-24-092 - PT-200 - Estrutura Metálica - Fabricação | I37: =SUM(I38:I38) -> 7289311.6 | V37: =V38 -> 0 | W37: =W38 -> 7289311.6 | X37: =X38 -> 522626.67 | Y37: =Y38 -> 2891867.6 | Z37: =Z38 -> 3553861.4 | AA37: =AA38 -> 592310.23 | AB37: =AB38 -> 0 | AC37: =AC38 -> 0 | ... AF37: =AF38 -> 7560665.9
B38: SS-39/2026 | C38: IN-5250-24-092 - PT-200 - Estrutura Metálica - Fabricação | D38: 1.2.22.1 | E38: Fabricação de estrutura | F38: kg | G38: 209211.81 | H38: 34.841778 | I38: =H38*G38 -> 7289311.6 | L38: =G38-K38 -> 209211.81 | M38: =SUM(MC_SS_39!H3:H15) -> 15000 | N38: =SUM(MC_SS_39!I3:I15) -> 83000 | O38: =SUM(MC_SS_39!J3:J15) -> 102000 | P38: =SUM(MC_SS_39!K3:K15) -> 17000 | Q38: =SUM(MC_SS_39!L3:L15) -> 0 | R38: =SUM(MC_SS_39!M3:M15) -> 0 | V38: =$H38*K38 -> 0 | W38: =$H38*L38 -> 7289311.6 | X38: =$H38*M38 -> 522626.67 | Y38: =$H38*N38 -> 2891867.6 | Z38: =$H38*O38 -> 3553861.4 | AA38: =$H38*P38 -> 592310.23 | AB38: =$H38*Q38 -> 0 | AC38: =$H38*R38 -> 0 | ... AE38: =$H38*T38 -> 0 | AF38: =SUM(X38:AE38) -> 7560665.9 | AH38: =L38-SUM(M38:T38) -> -7788.1868 | AI38: =W38-SUM(X38:AE38) -> -271354.28
B39: SS-44/2026 | C39: IN - 5250-24-085 - Phase-Out do Diesel S500 - Mudança 2.1 - Fabricação (Tubovias) | I39: =SUM(I40:I42) -> 876615.91 | V39: =SUM(V40:V42) -> 331297.35 | W39: =SUM(W40:W42) -> 545318.56 | X39: =SUM(X40:X42) -> 383499.72 | Y39: =SUM(Y40:Y42) -> 161818.85 | Z39: =SUM(Z40:Z42) -> 0 | AA39: =SUM(AA40:AA42) -> 0 | AB39: =SUM(AB40:AB42) -> 0 | AC39: =SUM(AC40:AC42) -> 0 | ... AF39: =SUM(AF40:AF42) -> 545318.56
B40: SS-44/2026 | C40: IN - 5250-24-085 - Phase-Out do Diesel S500 - Mudança 2.1 - Fabricação (Tubovias) | D40: 1.2.1.1 | E40: Tubulações (inclui suportes de tubulação) - Diâmetro menor ou igual a 1.1/2" | F40: kg | G40: 21.11723 | H40: 48.374646 | I40: =H40*G40 -> 1021.5385 | L40: =G40-K40 -> 21.11723 | M40: =SUM(MC_SS_44!N3:N15) -> 21.11723 | N40: =SUM(MC_SS_44!P3:P15) -> 0 | V40: =$H40*K40 -> 0 | W40: =$H40*L40 -> 1021.5385 | X40: =$H40*M40 -> 1021.5385 | Y40: =$H40*N40 -> 0 | Z40: =$H40*O40 -> 0 | AA40: =$H40*P40 -> 0 | AB40: =$H40*Q40 -> 0 | AC40: =$H40*R40 -> 0 | ... AE40: =$H40*T40 -> 0 | AF40: =SUM(X40:AE40) -> 1021.5385 | AH40: =L40-SUM(M40:T40) -> 0 | AI40: =W40-SUM(X40:AE40) -> 0
B41: SS-44/2026 | C41: IN - 5250-24-085 - Phase-Out do Diesel S500 - Mudança 2.1 - Fabricação (Tubovias) | D41: 1.2.1.2 | E41: Tubulações (inclui suportes de tubulação) - Diâmetro maior do que 1.1/2" até 6" | F41: kg | G41: 19706.05 | H41: 36.221137 | I41: =H41*G41 -> 713775.53 | K41: 9146.52 | L41: =G41-K41 -> 10559.53 | M41: =L41 -> 10559.53 | N41: =SUM(MC_SS_44!Q3:Q15) -> 0 | V41: =$H41*K41 -> 331297.35 | W41: =$H41*L41 -> 382478.18 | X41: =$H41*M41 -> 382478.18 | Y41: =$H41*N41 -> 0 | Z41: =$H41*O41 -> 0 | AA41: =$H41*P41 -> 0 | AB41: =$H41*Q41 -> 0 | AC41: =$H41*R41 -> 0 | ... AE41: =$H41*T41 -> 0 | AF41: =SUM(X41:AE41) -> 382478.18 | AH41: =L41-SUM(M41:T41) -> 0 | AI41: =W41-SUM(X41:AE41) -> 0
B42: SS-44/2026 | C42: IN - 5250-24-085 - Phase-Out do Diesel S500 - Mudança 2.1 - Fabricação (Tubovias) | D42: 1.2.8.3 | E42: Radiografia de Juntas | F42: un | G42: 47 | H42: 3442.9542 | I42: =H42*G42 -> 161818.85 | L42: =G42-K42 -> 47 | N42: =G42 -> 47 | V42: =$H42*K42 -> 0 | W42: =$H42*L42 -> 161818.85 | X42: =$H42*M42 -> 0 | Y42: =$H42*N42 -> 161818.85 | Z42: =$H42*O42 -> 0 | AA42: =$H42*P42 -> 0 | AB42: =$H42*Q42 -> 0 | AC42: =$H42*R42 -> 0 | ... AE42: =$H42*T42 -> 0 | AF42: =SUM(X42:AE42) -> 161818.85 | AH42: =L42-SUM(M42:T42) -> 0 | AI42: =W42-SUM(X42:AE42) -> 0
...

Sheet Planilha3
A1: Verificar executados
A3: SS-1/2026 | B3: Adequação Escadas de Marinheiro - Execução - UN 01,102,108,109,209 - UDAV 01/02
A4: SS-2/2026 | B4: IN-5250-24-092 - PT-200 - Escavação Manual para Pré Furos e Fundação
A5: SS-36/2026 | B5: Manutenção Civil - Linha do Flare na Av. 8
A6: SS-44/2026 | B6: IN - 5250-24-085 - Phase-Out do Diesel S500 - Mudança 2.1 - Fabricação (Tubovias)
A7: SS-60/2025 | B7: IN-5250-25-014 - ETDI - DESARENADOR
A8: SS-61/2025 | B8: IN-5250-20-001 - ETDI - REDE CONTAMINADA
A9: SS-62/2025 | B9: IN - 5250-25-005 - ETDI - FRENTE 01 - BOMBAS DO PPI - ELÉTRICA
A10: SS-66/2026 | B10: CALDEIRAS 0121-F-001 ABC - FUNDAÇÃO PARA GRUA
A11: SS-73/2025 | B11: IN - 5250-20-001 - ETDI - BOMBAS DO PPI - CIVIL
A12: SS-74/2025 | B12: IN-5250-25-015 - ETDI - CONTAMINADA FASE 2 - CIVIL
A13: SS-79/2026 | B13: UNIDADE 47 - TANQUE DE ÁGUA ÁCIDA
A14: SS-94/2025 | B14: IN - 5250-20-001 - ETDI - BOMBAS DO PPI - MECANICA
... A16: SS-97/2025 | B16: IN - 5250-25-011 - Melhoria acesso bloco P 27-TQ-01 K e M - Montagem

Sheet CRONO BENS
K2: FISICO_QUANTIDADES | W2: FINANCEIRO_VALOR (R$)
K3: Medido | L3: Saldo | M3: 46113 | N3: 46143 | O3: 46174 | P3: 46204 | Q3: 46235 | R3: 46266 | S3: 46296 | T3: 46327 | U3: 46357 | W3: Acum | X3: Saldo | Y3: 46143 | Z3: 46174 | AA3: 46204 | AB3: 46235 | AC3: 46266 | AD3: 46296 | AE3: 46327 | AF3: 46357 | AG3: TOTAL MAIO A DEZ/2026 | AI3: CONF.FIS | AJ3: CONF.R$
B4: SS | C4: DESCRIÇÃO-SS | D4: ITEM | E4: DESCRIÇÃO-ITEM | F4: UN | G4: Qtd | H4: PREÇO UNITÁRIO (R$) | I4: PREÇO TOTAL (R$)
C6: FORNECIMENTO DE BENS - TOTAL GERAL | W6: =SUM(W7,W10,W14,W16,W19,W23,W27,W30,W37,W39,W41,W61) -> 928949.64 | X6: =SUM(X7,X10,X14,X16,X19,X23,X27,X30,X37,X39,X41,X61) -> 3971639.9 | Y6: =SUM(Y7,Y10,Y14,Y16,Y19,Y23,Y27,Y30,Y37,Y39,Y41,Y61) -> 566418.96 | Z6: =SUM(Z7,Z10,Z14,Z16,Z19,Z23,Z27,Z30,Z37,Z39,Z41,Z61) -> 1413110.6 | AA6: =SUM(AA7,AA10,AA14,AA16,AA19,AA23,AA27,AA30,AA37,AA39,AA41,AA61) -> 1039652.3 | AB6: =SUM(AB7,AB10,AB14,AB16,AB19,AB23,AB27,AB30,AB37,AB39,AB41,AB61) -> 970841.89 | AC6: =SUM(AC7,AC10,AC14,AC16,AC19,AC23,AC27,AC30,AC37,AC39,AC41,AC61) -> 0 | AD6: =SUM(AD7,AD10,AD14,AD16,AD19,AD23,AD27,AD30,AD37,AD39,AD41,AD61) -> 0 | ... AG6: =SUM(AG7,AG10,AG14,AG16,AG19,AG23,AG27,AG30,AG37,AG39,AG41,AG61) -> 3990023.8
B7: SS-184/2026 | C7: Rede Envelopada - Armazéns S5 x S6 - Bens | I7: =SUM(I8:I9) -> 31206.549 | W7: =SUM(W8:W9) -> 0 | X7: =SUM(X8:X9) -> 31206.549 | Y7: =SUM(Y8:Y9) -> 0 | Z7: =SUM(Z8:Z9) -> 31206.549 | AA7: =SUM(AA8:AA9) -> 0 | AB7: =SUM(AB8:AB9) -> 0 | AC7: =SUM(AC8:AC9) -> 0 | AD7: =SUM(AD8:AD9) -> 0 | ... AG7: =SUM(AG8:AG9) -> 31206.549
B8: SS-184/2026 | C8: Rede Envelopada - Armazéns S5 x S6 - Bens | D8: 2.2.1.155 | E8: CABO EL. NU DE COBRE CL.2A 70MM² | F8: M | G8: 200 | H8: 42.655855 | I8: =H8*G8 -> 8531.1711 | L8: =G8-K8 -> 200 | O8: =G8 -> 200 | W8: =$H8*K8 -> 0 | X8: =$H8*L8 -> 8531.1711 | Y8: =$H8*N8 -> 0 | Z8: =$H8*O8 -> 8531.1711 | AA8: =$H8*P8 -> 0 | AB8: =$H8*Q8 -> 0 | AC8: =$H8*R8 -> 0 | AD8: =$H8*S8 -> 0 | AE8: =$H8*T8 -> 0 | AF8: =$H8*U8 -> 0 | AG8: =SUM(Y8:AF8) -> 8531.1711 | AI8: =L8-SUM(M8:U8) -> 0 | AJ8: =X8-SUM(Y8:AF8) -> 0
B9: SS-184/2026 | C9: Rede Envelopada - Armazéns S5 x S6 - Bens | D9: 2.2.3.6 | E9: Aço carbono com revestimento protetor de zinco (galvanizado a fogo)/ DN 4" | F9: M | G9: 187 | H9: 121.25871 | I9: =H9*G9 -> 22675.378 | L9: =G9-K9 -> 187 | O9: =G9 -> 187 | W9: =$H9*K9 -> 0 | X9: =$H9*L9 -> 22675.378 | Y9: =$H9*N9 -> 0 | Z9: =$H9*O9 -> 22675.378 | AA9: =$H9*P9 -> 0 | AB9: =$H9*Q9 -> 0 | AC9: =$H9*R9 -> 0 | AD9: =$H9*S9 -> 0 | AE9: =$H9*T9 -> 0 | AF9: =$H9*U9 -> 0 | AG9: =SUM(Y9:AF9) -> 22675.378 | AI9: =L9-SUM(M9:U9) -> 0 | AJ9: =X9-SUM(Y9:AF9) -> 0
B10: SS-152/2026 | C10: U-623 - RELOCAÇÃO TUBULAÇÃO RACE - BENS | I10: =SUM(I11:I13) -> 192523.85 | W10: =SUM(W11:W13) -> 0 | X10: =SUM(X11:X13) -> 192523.85 | Y10: =SUM(Y11:Y13) -> 0 | Z10: =SUM(Z11:Z13) -> 192523.85 | AA10: =SUM(AA11:AA13) -> 0 | AB10: =SUM(AB11:AB13) -> 0 | AC10: =SUM(AC11:AC13) -> 0 | AD10: =SUM(AD11:AD13) -> 0 | ... AG10: =SUM(AG11:AG13) -> 192523.85
B11: SS-152/2026 | C11: U-623 - RELOCAÇÃO TUBULAÇÃO RACE - BENS | D11: 2.1.2.1 | E11: Tubos de condução em aço carbono | F11: KG | G11: 3209.502 | H11: 36.384822 | I11: =H11*G11 -> 116777.16 | L11: =G11-K11 -> 3209.502 | O11: =L11 -> 3209.502 | W11: =$H11*K11 -> 0 | X11: =$H11*L11 -> 116777.16 | Y11: =$H11*N11 -> 0 | Z11: =$H11*O11 -> 116777.16 | AA11: =$H11*P11 -> 0 | AB11: =$H11*Q11 -> 0 | AC11: =$H11*R11 -> 0 | AD11: =$H11*S11 -> 0 | AE11: =$H11*T11 -> 0 | AF11: =$H11*U11 -> 0 | AG11: =SUM(Y11:AF11) -> 116777.16 | AI11: =L11-SUM(M11:U11) -> 0 | AJ11: =X11-SUM(Y11:AF11) -> 0
B12: SS-152/2026 | C12: U-623 - RELOCAÇÃO TUBULAÇÃO RACE - BENS | D12: 2.1.3.1 | E12: Acessórios em aço carbono | F12: KG | G12: 549.134 | H12: 132.51219 | I12: =H12*G12 -> 72766.951 | L12: =G12-K12 -> 549.134 | O12: =L12 -> 549.134 | W12: =$H12*K12 -> 0 | X12: =$H12*L12 -> 72766.951 | Y12: =$H12*N12 -> 0 | Z12: =$H12*O12 -> 72766.951 | AA12: =$H12*P12 -> 0 | AB12: =$H12*Q12 -> 0 | AC12: =$H12*R12 -> 0 | AD12: =$H12*S12 -> 0 | AE12: =$H12*T12 -> 0 | AF12: =$H12*U12 -> 0 | AG12: =SUM(Y12:AF12) -> 72766.951 | AI12: =L12-SUM(M12:U12) -> 0 | AJ12: =X12-SUM(Y12:AF12) -> 0
B13: SS-152/2026 | C13: U-623 - RELOCAÇÃO TUBULAÇÃO RACE - BENS | D13: 2.1.4.1 | E13: Material de referência ASTM A193 Gr B7 | F13: KG | G13: 54.88 | H13: 54.295645 | I13: =H13*G13 -> 2979.745 | L13: =G13-K13 -> 54.88 | O13: =L13 -> 54.88 | W13: =$H13*K13 -> 0 | X13: =$H13*L13 -> 2979.745 | Y13: =$H13*N13 -> 0 | Z13: =$H13*O13 -> 2979.745 | AA13: =$H13*P13 -> 0 | AB13: =$H13*Q13 -> 0 | AC13: =$H13*R13 -> 0 | AD13: =$H13*S13 -> 0 | AE13: =$H13*T13 -> 0 | AF13: =$H13*U13 -> 0 | AG13: =SUM(Y13:AF13) -> 2979.745 | AI13: =L13-SUM(M13:U13) -> 0 | AJ13: =X13-SUM(Y13:AF13) -> 0
B14: SS-139/2026 | C14: UN-623 - CASA DE QUÍMICOS - FORNECIMENTO DE BENS | I14: =SUM(I15:I15) -> 3597.6295 | W14: =SUM(W15:W15) -> 0 | X14: =SUM(X15:X15) -> 3597.6295 | Y14: =SUM(Y15:Y15) -> 0 | Z14: =SUM(Z15:Z15) -> 3597.6295 | AA14: =SUM(AA15:AA15) -> 0 | AB14: =SUM(AB15:AB15) -> 0 | AC14: =SUM(AC15:AC15) -> 0 | AD14: =SUM(AD15:AD15) -> 0 | ... AG14: =SUM(AG15:AG15) -> 3597.6295
B15: SS-139/2026 | C15: UN-623 - CASA DE QUÍMICOS - FORNECIMENTO DE BENS | D15: 2.1.4.1 | E15: Material de referência ASTM A193 Gr B7 | F15: KG | G15: 66.26 | H15: 54.295645 | I15: =H15*G15 -> 3597.6295 | L15: =G15-K15 -> 66.26 | O15: =L15 -> 66.26 | W15: =$H15*K15 -> 0 | X15: =$H15*L15 -> 3597.6295 | Y15: =$H15*N15 -> 0 | Z15: =$H15*O15 -> 3597.6295 | AA15: =$H15*P15 -> 0 | AB15: =$H15*Q15 -> 0 | AC15: =$H15*R15 -> 0 | AD15: =$H15*S15 -> 0 | AE15: =$H15*T15 -> 0 | AF15: =$H15*U15 -> 0 | AG15: =SUM(Y15:AF15) -> 3597.6295 | AI15: =L15-SUM(M15:U15) -> 0 | AJ15: =X15-SUM(Y15:AF15) -> 0
B16: SS-128/2026 | C16: FORNECIMENTO DE BENS - ALIMENTAÇÕES PROVISÓRIAS TAF - SDCD UDAV II | I16: =SUM(I17:I18) -> 777.83798 | W16: =SUM(W17:W18) -> 0 | X16: =SUM(X17:X18) -> 777.83798 | Y16: =SUM(Y17:Y18) -> 0 | Z16: =SUM(Z17:Z18) -> 777.83798 | AA16: =SUM(AA17:AA18) -> 0 | AB16: =SUM(AB17:AB18) -> 0 | AC16: =SUM(AC17:AC18) -> 0 | AD16: =SUM(AD17:AD18) -> 0 | ... AG16: =SUM(AG17:AG18) -> 777.83798
B17: SS-128/2026 | C17: FORNECIMENTO DE BENS - ALIMENTAÇÕES PROVISÓRIAS TAF - SDCD UDAV II | D17: 2.2.1.35 | E17: Cabo potência até 1kV (de 3x até 4x) de 2,5mm² a 4,0 mm², EPR/HEPR, ST1/ST2 | F17: M | G17: 40 | H17: 9.1244181 | I17: =H17*G17 -> 364.97672 | L17: =G17-K17 -> 40 | O17: =G17 -> 40 | W17: =$H17*K17 -> 0 | X17: =$H17*L17 -> 364.97672 | Y17: =$H17*N17 -> 0 | Z17: =$H17*O17 -> 364.97672 | AA17: =$H17*P17 -> 0 | AB17: =$H17*Q17 -> 0 | AC17: =$H17*R17 -> 0 | AD17: =$H17*S17 -> 0 | AE17: =$H17*T17 -> 0 | AF17: =$H17*U17 -> 0 | AG17: =SUM(Y17:AF17) -> 364.97672 | AI17: =L17-SUM(M17:U17) -> 0 | AJ17: =X17-SUM(Y17:AF17) -> 0
B18: SS-128/2026 | C18: FORNECIMENTO DE BENS - ALIMENTAÇÕES PROVISÓRIAS TAF - SDCD UDAV II | D18: 2.2.1.158 | E18: CABO EL. NU DE COBRE CL.2C 16MM² | F18: M | G18: 20 | H18: 20.643063 | I18: =H18*G18 -> 412.86126 | L18: =G18-K18 -> 20 | O18: =G18 -> 20 | W18: =$H18*K18 -> 0 | X18: =$H18*L18 -> 412.86126 | Y18: =$H18*N18 -> 0 | Z18: =$H18*O18 -> 412.86126 | AA18: =$H18*P18 -> 0 | AB18: =$H18*Q18 -> 0 | AC18: =$H18*R18 -> 0 | AD18: =$H18*S18 -> 0 | AE18: =$H18*T18 -> 0 | AF18: =$H18*U18 -> 0 | AG18: =SUM(Y18:AF18) -> 412.86126 | AI18: =L18-SUM(M18:U18) -> 0 | AJ18: =X18-SUM(Y18:AF18) -> 0
B19: SS-108/2026 | C19: IN - 5250-24-085 - Phase-Out do Diesel S500 - Mudança 4.1 - Aquisição de Bens (Tubovias) | I19: =SUM(I20:I22) -> 162194.8 | W19: =SUM(W20:W22) -> 0 | X19: =SUM(X20:X22) -> 162194.8 | Y19: =SUM(Y20:Y22) -> 0 | Z19: =SUM(Z20:Z22) -> 162194.8 | AA19: =SUM(AA20:AA22) -> 0 | AB19: =SUM(AB20:AB22) -> 0 | AC19: =SUM(AC20:AC22) -> 0 | AD19: =SUM(AD20:AD22) -> 0 | ... AG19: =SUM(AG20:AG22) -> 162194.8
B20: SS-108/2026 | C20: IN - 5250-24-085 - Phase-Out do Diesel S500 - Mudança 4.1 - Aquisição de Bens (Tubovias) | D20: 2.1.1.1 | E20: Chapas e perfis estruturais em aço carbono | F20: KG | G20: 193.1593 | H20: 26.960219 | I20: =H20*G20 -> 5207.6171 | L20: =G20-K20 -> 193.1593 | O20: =G20 -> 193.1593 | W20: =$H20*K20 -> 0 | X20: =$H20*L20 -> 5207.6171 | Y20: =$H20*N20 -> 0 | Z20: =$H20*O20 -> 5207.6171 | AA20: =$H20*P20 -> 0 | AB20: =$H20*Q20 -> 0 | AC20: =$H20*R20 -> 0 | AD20: =$H20*S20 -> 0 | AE20: =$H20*T20 -> 0 | AF20: =$H20*U20 -> 0 | AG20: =SUM(Y20:AF20) -> 5207.6171 | AI20: =L20-SUM(M20:U20) -> 0 | AJ20: =X20-SUM(Y20:AF20) -> 0
B21: SS-108/2026 | C21: IN - 5250-24-085 - Phase-Out do Diesel S500 - Mudança 4.1 - Aquisição de Bens (Tubovias) | D21: 2.1.2.1 | E21: Tubos de condução em aço carbono | F21: KG | G21: 2417.8148 | H21: 36.384822 | I21: =H21*G21 -> 87971.761 | L21: =G21-K21 -> 2417.8148 | O21: =G21 -> 2417.8148 | W21: =$H21*K21 -> 0 | X21: =$H21*L21 -> 87971.761 | Y21: =$H21*N21 -> 0 | Z21: =$H21*O21 -> 87971.761 | AA21: =$H21*P21 -> 0 | AB21: =$H21*Q21 -> 0 | AC21: =$H21*R21 -> 0 | AD21: =$H21*S21 -> 0 | AE21: =$H21*T21 -> 0 | AF21: =$H21*U21 -> 0 | AG21: =SUM(Y21:AF21) -> 87971.761 | AI21: =L21-SUM(M21:U21) -> 0 | AJ21: =X21-SUM(Y21:AF21) -> 0
B22: SS-108/2026 | C22: IN - 5250-24-085 - Phase-Out do Diesel S500 - Mudança 4.1 - Aquisição de Bens (Tubovias) | D22: 2.1.3.1 | E22: Acessórios em aço carbono | F22: KG | G22: 520.82316 | H22: 132.51219 | I22: =H22*G22 -> 69015.419 | L22: =G22-K22 -> 520.82316 | O22: =G22 -> 520.82316 | W22: =$H22*K22 -> 0 | X22: =$H22*L22 -> 69015.419 | Y22: =$H22*N22 -> 0 | Z22: =$H22*O22 -> 69015.419 | AA22: =$H22*P22 -> 0 | AB22: =$H22*Q22 -> 0 | AC22: =$H22*R22 -> 0 | AD22: =$H22*S22 -> 0 | AE22: =$H22*T22 -> 0 | AF22: =$H22*U22 -> 0 | AG22: =SUM(Y22:AF22) -> 69015.419 | AI22: =L22-SUM(M22:U22) -> 0 | AJ22: =X22-SUM(Y22:AF22) -> 0
B23: SS-43/2026 | C23: IN - 5250-24-085 - Phase-Out do Diesel S500 - Mudança 2.1 - Aquisição de Bens (Tubovias) | I23: =SUM(I24:I26) -> 606944.81 | W23: =SUM(W24:W26) -> 559174.06 | X23: =SUM(X24:X26) -> 47770.757 | Y23: =SUM(Y24:Y26) -> 47770.757 | Z23: =SUM(Z24:Z26) -> 0 | AA23: =SUM(AA24:AA26) -> 0 | AB23: =SUM(AB24:AB26) -> 0 | AC23: =SUM(AC24:AC26) -> 0 | AD23: =SUM(AD24:AD26) -> 0 | ... AG23: =SUM(AG24:AG26) -> 47770.757
B24: SS-43/2026 | C24: IN - 5250-24-085 - Phase-Out do Diesel S500 - Mudança 2.1 - Aquisição de Bens (Tubovias) | D24: 2.1.1.1 | E24: Chapas e perfis estruturais em aço carbono | F24: KG | G24: 1771.8979 | H24: 26.960219 | I24: =H24*G24 -> 47770.757 | L24: =G24-K24 -> 1771.8979 | N24: =G24 -> 1771.8979 | W24: =$H24*K24 -> 0 | X24: =$H24*L24 -> 47770.757 | Y24: =$H24*N24 -> 47770.757 | Z24: =$H24*O24 -> 0 | AA24: =$H24*P24 -> 0 | AB24: =$H24*Q24 -> 0 | AC24: =$H24*R24 -> 0 | AD24: =$H24*S24 -> 0 | AE24: =$H24*T24 -> 0 | AF24: =$H24*U24 -> 0 | AG24: =SUM(Y24:AF24) -> 47770.757 | AI24: =L24-SUM(M24:U24) -> 0 | AJ24: =X24-SUM(Y24:AF24) -> 0
B25: SS-43/2026 | C25: IN - 5250-24-085 - Phase-Out do Diesel S500 - Mudança 2.1 - Aquisição de Bens (Tubovias) | D25: 2.1.2.1 | E25: Tubos de condução em aço carbono | F25: KG | G25: 14736.06 | H25: 36.384822 | I25: =H25*G25 -> 536168.92 | K25: 14736.06 | L25: =G25-K25 -> 0 | W25: =$H25*K25 -> 536168.92 | X25: =$H25*L25 -> 0 | Y25: =$H25*N25 -> 0 | Z25: =$H25*O25 -> 0 | AA25: =$H25*P25 -> 0 | AB25: =$H25*Q25 -> 0 | AC25: =$H25*R25 -> 0 | AD25: =$H25*S25 -> 0 | AE25: =$H25*T25 -> 0 | AF25: =$H25*U25 -> 0 | AG25: =SUM(Y25:AF25) -> 0 | AI25: =L25-SUM(M25:U25) -> 0 | AJ25: =X25-SUM(Y25:AF25) -> 0
B26: SS-43/2026 | C26: IN - 5250-24-085 - Phase-Out do Diesel S500 - Mudança 2.1 - Aquisição de Bens (Tubovias) | D26: 2.1.3.1 | E26: Acessórios em aço carbono | F26: KG | G26: 173.60772 | H26: 132.51219 | I26: =H26*G26 -> 23005.14 | K26: 173.60772 | L26: =G26-K26 -> 0 | W26: =$H26*K26 -> 23005.14 | X26: =$H26*L26 -> 0 | Y26: =$H26*N26 -> 0 | Z26: =$H26*O26 -> 0 | AA26: =$H26*P26 -> 0 | AB26: =$H26*Q26 -> 0 | AC26: =$H26*R26 -> 0 | AD26: =$H26*S26 -> 0 | AE26: =$H26*T26 -> 0 | AF26: =$H26*U26 -> 0 | AG26: =SUM(Y26:AF26) -> 0 | AI26: =L26-SUM(M26:U26) -> 0 | AJ26: =X26-SUM(Y26:AF26) -> 0
B27: SS-38/2026 | C27: IN-5250-24-092 - PT-200 - Estrutura Metálica - Fornecimento de Bens | I27: =SUM(I28:I29) -> 3219797 | W27: =SUM(W28:W29) -> 0 | X27: =SUM(X28:X29) -> 3219797 | Y27: =SUM(Y28:Y29) -> 404403.29 | Z27: =SUM(Z28:Z29) -> 804899.54 | AA27: =SUM(AA28:AA29) -> 1039652.3 | AB27: =SUM(AB28:AB29) -> 970841.89 | AC27: =SUM(AC28:AC29) -> 0 | AD27: =SUM(AD28:AD29) -> 0 | ... AG27: =SUM(AG28:AG29) -> 3219797
B28: SS-38/2026 | C28: IN-5250-24-092 - PT-200 - Estrutura Metálica - Fornecimento de Bens | D28: 2.1.1.1 | E28: Chapas e perfis estruturais em aço carbono | F28: KG | G28: 119420.33 | H28: 26.960219 | I28: =H28*G28 -> 3219598.2 | L28: =G28-K28 -> 119420.33 | N28: 15000 | O28: 29855.081 | P28: 38555.081 | Q28: =G28-O28-P28-N28 -> 36010.163 | W28: =$H28*K28 -> 0 | X28: =$H28*L28 -> 3219598.2 | Y28: =$H28*N28 -> 404403.29 | Z28: =$H28*O28 -> 804899.54 | AA28: =$H28*P28 -> 1039453.5 | AB28: =$H28*Q28 -> 970841.89 | AC28: =$H28*R28 -> 0 | AD28: =$H28*S28 -> 0 | AE28: =$H28*T28 -> 0 | AF28: =$H28*U28 -> 0 | AG28: =SUM(Y28:AF28) -> 3219598.2 | AI28: =L28-SUM(M28:U28) -> 0 | AJ28: =X28-SUM(Y28:AF28) -> 0
B29: SS-38/2026 | C29: IN-5250-24-092 - PT-200 - Estrutura Metálica - Fornecimento de Bens | D29: 2.1.4.1 | E29: Material de referência ASTM A193 Gr B7 | F29: KG | G29: 3.6618 | H29: 54.295645 | I29: =H29*G29 -> 198.81979 | L29: =G29-K29 -> 3.6618 | P29: =L29 -> 3.6618 | W29: =$H29*K29 -> 0 | X29: =$H29*L29 -> 198.81979 | Y29: =$H29*N29 -> 0 | Z29: =$H29*O29 -> 0 | AA29: =$H29*P29 -> 198.81979 | AB29: =$H29*Q29 -> 0 | AC29: =$H29*R29 -> 0 | AD29: =$H29*S29 -> 0 | AE29: =$H29*T29 -> 0 | AF29: =$H29*U29 -> 0 | AG29: =SUM(Y29:AF29) -> 198.81979 | AI29: =L29-SUM(M29:U29) -> 0 | AJ29: =X29-SUM(Y29:AF29) -> 0
B30: SS-16/2026 | C30: PMBC - 5250-26-100 - HAZOP DA U-001 E U-101 - BENS | I30: =SUM(I31:I36) -> 16989.47 | W30: =SUM(W31:W36) -> 0 | X30: =SUM(X31:X36) -> 16989.47 | Y30: =SUM(Y31:Y36) -> 16989.47 | Z30: =SUM(Z31:Z36) -> 0 | AA30: =SUM(AA31:AA36) -> 0 | AB30: =SUM(AB31:AB36) -> 0 | AC30: =SUM(AC31:AC36) -> 0 | AD30: =SUM(AD31:AD36) -> 0 | ... AG30: =SUM(AG31:AG36) -> 16989.47
B31: SS-16/2026 | C31: PMBC - 5250-26-100 - HAZOP DA U-001 E U-101 - BENS | D31: 2.1.1.1 | E31: Chapas e perfis estruturais em aço carbono | F31: KG | G31: 0 | H31: 26.960219 | I31: =H31*G31 -> 0 | L31: =G31-K31 -> 0 | N31: =G31 -> 0 | W31: =$H31*K31 -> 0 | X31: =$H31*L31 -> 0 | Y31: =$H31*N31 -> 0 | Z31: =$H31*O31 -> 0 | AA31: =$H31*P31 -> 0 | AB31: =$H31*Q31 -> 0 | AC31: =$H31*R31 -> 0 | AD31: =$H31*S31 -> 0 | AE31: =$H31*T31 -> 0 | AF31: =$H31*U31 -> 0 | AG31: =SUM(Y31:AF31) -> 0 | AI31: =L31-SUM(M31:U31) -> 0 | AJ31: =X31-SUM(Y31:AF31) -> 0
B32: SS-16/2026 | C32: PMBC - 5250-26-100 - HAZOP DA U-001 E U-101 - BENS | D32: 2.1.2.1 | E32: Tubos de condução em aço carbono | F32: KG | G32: 44.5 | H32: 36.384822 | I32: =H32*G32 -> 1619.1246 | L32: =G32-K32 -> 44.5 | N32: =G32 -> 44.5 | W32: =$H32*K32 -> 0 | X32: =$H32*L32 -> 1619.1246 | Y32: =$H32*N32 -> 1619.1246 | Z32: =$H32*O32 -> 0 | AA32: =$H32*P32 -> 0 | AB32: =$H32*Q32 -> 0 | AC32: =$H32*R32 -> 0 | AD32: =$H32*S32 -> 0 | AE32: =$H32*T32 -> 0 | AF32: =$H32*U32 -> 0 | AG32: =SUM(Y32:AF32) -> 1619.1246 | AI32: =L32-SUM(M32:U32) -> 0 | AJ32: =X32-SUM(Y32:AF32) -> 0
