Workbook
Name \0: #REF!
Name \a: #N/A
Name \b: #N/A
Name \c: #N/A
Name \d: #N/A
Name \e: #N/A
Name \f: #N/A
Name \g: #N/A
Name \h: #N/A
Name \i: #N/A
Name \j: #N/A
Name \k: #REF!
Name \l: #REF!
Name \m: #N/A
Name \n: #REF!
Name \O: #REF!
Name \p: #N/A
Name \q: #N/A
Name \r: #N/A
Name \s: #N/A
Name \t: #N/A
Name \u: #N/A
Name \v: #N/A
Name \w: #N/A
Name \x: #N/A
Name \z: #N/A
Name _: #REF!
Name _______F99000: #REF!
Name ______F99000: #REF!
Name ____COD1: #REF!
Name ____COD10: #REF!
Name ____COD11: #REF!
Name ____COD13: #REF!
Name ____COD16: #REF!
Name ____COD17: #REF!
Name ____COD21: #REF!
Name ____COD23: #REF!
Name ____COD24: #REF!
Name ____COD28: #REF!
Name ____COD29: #REF!
Name ____COD32: #REF!
Name ____COD35: #REF!
Name ____COD36: #REF!
Name ____COD37: #REF!
Name ____COD41: #REF!
Name ____COD42: #REF!
Name ____COD43: #REF!
Name ____COD44: #REF!
Name ____COD46: #REF!
Name ____COD47: #REF!
Name ____COD49: #REF!
Name ____COD50: #REF!
Name ____COD55: #REF!
Name ____COD60: #REF!
Name ____COD62: #REF!
Name ____COD65: #REF!
Name ____COD66: #REF!
Name ____COD68: #REF!
Name ____COD8: #REF!
Name ____F99000: #REF!

Sheet Resumo Orçamento
A1: PAINEL DE GESTÃO - SS'S
A3: DETALHAMENTO DE VALORES - SALDO A FATURAR
A6: Status SAMC Real | B6: Soma de Valor Saldo | D6: Status SAMC Real | E6: Contagem de Número
A7: Aguardando Aprovação | B7: 5944747.5 | D7: Aguardando Aprovação | E7: 21
A8: Aguardando Class Contabil | B8: 13337712 | D8: Aguardando Class Contabil | E8: 19
A9: Aguardando Planejamento | B9: 0 | D9: Aguardando Planejamento | E9: 16
A10: Em Andamento | B10: 10624974 | D10: Em Andamento | E10: 42
A11: Em Revisão | B11: 2358365.8 | D11: Em Revisão | E11: 4
A12: Encaminhado p/ o fornecedor | B12: 13935253 | D12: Encaminhado p/ o fornecedor | E12: 14
A13: Reprovado pelo responsável | B13: 1015728.6 | D13: Reprovado pelo responsável | E13: 3
A14: Aguardando Aprovação da Revisão | B14: 977843.36 | D14: Aguardando Aprovação da Revisão | E14: 1
A15: Total Geral | B15: 48194624 | D15: Total Geral | E15: 120
A18: Disciplina | B18: Soma de Valor Saldo | D18: Disciplina | E18: Contagem de Valor Saldo
A19: Civil | B19: 13177656 | D19: Civil | E19: 49
A20: Elétrica | B20: 2733782.9 | D20: Elétrica | E20: 23
A21: Materiais | B21: 5520548.1 | D21: Materiais | E21: 13
A22: Mecânica | B22: 22536300 | D22: Mecânica | E22: 30
A23: Gestão | B23: 4222386 | D23: Gestão | E23: 5
A24: Total Geral | B24: 48190674 | D24: Total Geral | E24: 120
A27: Rótulos de Linha | B27: Soma de Valor Saldo
A28: GOG | B28: 13901736
A29: IN | B29: 34288938
A30: Total Geral | B30: 48190674

Sheet Resumo Andamento
A1: PAINEL DE GESTÃO - SS'S - ANDAMENTOS
A3: DETALHAMENTO DE STATUS DAS OBRAS
A6: STATUS DAS SS'S - ANDAMENTO | B6: CONTAGEM | D6: STATUS DAS SS'S - ANDAMENTO&SAMC | E6: CONTAGEM
A7: EM ANDAMENTO | B7: 28 | D7: EM ANDAMENTO | E7: 28 | G7: EM ANDAMENTO | H7: =GETPIVOTDATA("Status Obra",$A$6,"Status Obra","EM ANDAMENTO") -> 28
A8: EM PLANEJAMENTO | B8: 14 | D8: Aguardando Aprovação | E8: 3 | G8: EM PLANEJ | H8: =GETPIVOTDATA("Status Obra",$A$6,"Status Obra","EM PLANEJAMENTO") -> 14
A9: EM REPLANEJAMENTO | B9: 15 | D9: Aguardando Class Contabil | E9: 4 | G9: EM REPLANEJ | H9: =GETPIVOTDATA("Status Obra",$A$6,"Status Obra","EM REPLANEJAMENTO") -> 15
A10: INICIO ATRASADO | B10: 3 | D10: Em Andamento | E10: 15 | G10: INICIO ATRASADO | H10: =GETPIVOTDATA("Status Obra",$A$6,"Status Obra","INICIO ATRASADO") -> 3
A11: INICIO CURTO PRAZO | B11: 15 | D11: Em Revisão | E11: 1 | G11: INICIO CURTO PRAZO | H11: =GETPIVOTDATA("Status Obra",$A$6,"Status Obra","INICIO CURTO PRAZO") -> 15
A12: INICIO MEDIO PRAZO | B12: 2 | D12: Encaminhado p/ o fornecedor | E12: 4 | G12: INICIO MEDIO PRAZO | H12: =GETPIVOTDATA("Status Obra",$A$6,"Status Obra","INICIO MEDIO PRAZO") -> 2
A13: MATERIAIS | B13: 14 | D13: Reprovado pelo responsável | E13: 1 | G13: MATERIAIS | H13: 14
A14: PROJETO | B14: 6 | D14: EM PLANEJAMENTO | E14: 14 | G14: PROJETO | H14: 6
A15: ROTINA | B15: 14 | D15: Aguardando Planejamento | E15: 14 | G15: ROTINA | H15: 14
A16: STAND BY | B16: 1 | D16: EM REPLANEJAMENTO | E16: 15 | G16: STAND BY | H16: 1
A17: TOPOGRAFIA | B17: 8 | D17: Aguardando Aprovação | E17: 1 | G17: TOPOGRAFIA | H17: 8
A18: Total Geral | B18: 120 | D18: Aguardando Aprovação da Revisão | E18: 1
D19: Aguardando Class Contabil | E19: 1
D20: Em Andamento | E20: 10
D21: Em Revisão | E21: 1
D22: Reprovado pelo responsável | E22: 1
D23: INICIO ATRASADO | E23: 3
D24: Aguardando Aprovação | E24: 3
D25: INICIO CURTO PRAZO | E25: 15
D26: Aguardando Aprovação | E26: 5
D27: Aguardando Class Contabil | E27: 8
D28: Encaminhado p/ o fornecedor | E28: 2
D29: INICIO MEDIO PRAZO | E29: 2
D30: Aguardando Class Contabil | E30: 1
... D54: Total Geral | E54: 120

Sheet Base dados
A1: Número | B1: Título | C1: IN-GOG | D1: Status Real | E1: Valor Global | F1: Faturado Acumulado | G1: Valor Saldo | H1: Tipo - SS | I1: Local de Execução de Serviço | J1: Início BL | K1: Término BL
A2: SS-60/2025 | B2: IN-5250-25-014 - ETDI - DESARENADOR | C2: IN | D2: =VLOOKUP(Tabela1[[#This Row],[Número]],SAMC!A:F,6,0) -> Em andamento | E2: 738262.96 | F2: 473057.68 | G2: =Tabela1[[#This Row],[Valor Global]]-Tabela1[[#This Row],[Faturado Acumulado]] -> 265205.29 | H2: =VLOOKUP(Tabela1[[#This Row],[Número]],SAMC!A:F,4,0) -> Civil | I2: =VLOOKUP(Tabela1[[#This Row],[Número]],SAMC!A:F,3,0) -> Civil (projeto e manutenção civil) - Betim
A3: SS-61/2025 | B3: IN-5250-20-001 - ETDI - REDE CONTAMINADA | C3: IN | D3: =VLOOKUP(Tabela1[[#This Row],[Número]],SAMC!A:F,6,0) -> Em andamento | E3: 3271160.5 | F3: 2621074.1 | G3: =Tabela1[[#This Row],[Valor Global]]-Tabela1[[#This Row],[Faturado Acumulado]] -> 650086.43 | H3: =VLOOKUP(Tabela1[[#This Row],[Número]],SAMC!A:F,4,0) -> Civil | I3: =VLOOKUP(Tabela1[[#This Row],[Número]],SAMC!A:F,3,0) -> Civil (projeto e manutenção civil) - Betim
A4: SS-62/2025 | B4: IN - 5250-25-005 - ETDI - FRENTE 01 - BOMBAS DO PPI - ELÉTRICA | C4: IN | D4: =VLOOKUP(Tabela1[[#This Row],[Número]],SAMC!A:F,6,0) -> Em andamento | E4: 1007169.5 | F4: 766312.69 | G4: =Tabela1[[#This Row],[Valor Global]]-Tabela1[[#This Row],[Faturado Acumulado]] -> 240856.85 | H4: =VLOOKUP(Tabela1[[#This Row],[Número]],SAMC!A:F,4,0) -> Elétrica e Instrumentação | I4: =VLOOKUP(Tabela1[[#This Row],[Número]],SAMC!A:F,3,0) -> Elétrica e Instrumentação- Betim
A5: SS-73/2025 | B5: IN - 5250-20-001 - ETDI - BOMBAS DO PPI - CIVIL | C5: IN | D5: =VLOOKUP(Tabela1[[#This Row],[Número]],SAMC!A:F,6,0) -> Em andamento | E5: 218906.28 | F5: 32603.102 | G5: =Tabela1[[#This Row],[Valor Global]]-Tabela1[[#This Row],[Faturado Acumulado]] -> 186303.18 | H5: =VLOOKUP(Tabela1[[#This Row],[Número]],SAMC!A:F,4,0) -> Civil | I5: =VLOOKUP(Tabela1[[#This Row],[Número]],SAMC!A:F,3,0) -> Civil (projeto e manutenção civil) - Betim
A6: SS-74/2025 | B6: IN-5250-25-015 - ETDI - CONTAMINADA FASE 2 - CIVIL | C6: IN | D6: =VLOOKUP(Tabela1[[#This Row],[Número]],SAMC!A:F,6,0) -> Em andamento | E6: 5974363.8 | F6: 4687938.6 | G6: =Tabela1[[#This Row],[Valor Global]]-Tabela1[[#This Row],[Faturado Acumulado]] -> 1286425.3 | H6: =VLOOKUP(Tabela1[[#This Row],[Número]],SAMC!A:F,4,0) -> Civil | I6: =VLOOKUP(Tabela1[[#This Row],[Número]],SAMC!A:F,3,0) -> Civil (projeto e manutenção civil) - Betim
A7: SS-76/2025 | B7: IN-5250-23-014 - Novo Laboratório de Integridade da IE | C7: IN | D7: =VLOOKUP(Tabela1[[#This Row],[Número]],SAMC!A:F,6,0) -> Em Revisão | E7: =1646241.24/0.9075 -> 1814039.9 | F7: 551331.87 | G7: =Tabela1[[#This Row],[Valor Global]]-Tabela1[[#This Row],[Faturado Acumulado]] -> 1262708.1 | H7: =VLOOKUP(Tabela1[[#This Row],[Número]],SAMC!A:F,4,0) -> Civil | I7: =VLOOKUP(Tabela1[[#This Row],[Número]],SAMC!A:F,3,0) -> Civil (projeto e manutenção civil) - Betim
A8: SS-93/2025 | B8: Reforço do Muro da APAE | C8: GOG | D8: =VLOOKUP(Tabela1[[#This Row],[Número]],SAMC!A:F,6,0) -> Aguardando classif contabil | E8: 643934.46 | F8: 0 | G8: =Tabela1[[#This Row],[Valor Global]]-Tabela1[[#This Row],[Faturado Acumulado]] -> 643934.46 | H8: =VLOOKUP(Tabela1[[#This Row],[Número]],SAMC!A:F,4,0) -> Civil | I8: =VLOOKUP(Tabela1[[#This Row],[Número]],SAMC!A:F,3,0) -> CIVIL (Projetos e Monit e Manutenção de Barragem) - Ibirité
A9: SS-94/2025 | B9: IN - 5250-20-001 - ETDI - BOMBAS DO PPI - MECANICA | C9: IN | D9: =VLOOKUP(Tabela1[[#This Row],[Número]],SAMC!A:F,6,0) -> Em Andamento | E9: 566916.41 | F9: 84235.63 | G9: =Tabela1[[#This Row],[Valor Global]]-Tabela1[[#This Row],[Faturado Acumulado]] -> 482680.78 | H9: =VLOOKUP(Tabela1[[#This Row],[Número]],SAMC!A:F,4,0) -> Mecânica e Caldeiraria | I9: =VLOOKUP(Tabela1[[#This Row],[Número]],SAMC!A:F,3,0) -> Mecânica - Betim
A10: SS-96/2025 | B10: IN - 5250-25-010 - Melhoria acesso bloco K 27-TQ-01 C e D - Montagem | C10: IN | D10: =VLOOKUP(Tabela1[[#This Row],[Número]],SAMC!A:F,6,0) -> Em Revisão | E10: 1066348.1 | F10: 391705.25 | G10: =Tabela1[[#This Row],[Valor Global]]-Tabela1[[#This Row],[Faturado Acumulado]] -> 674642.88 | H10: =VLOOKUP(Tabela1[[#This Row],[Número]],SAMC!A:F,4,0) -> Mecânica e Caldeiraria | I10: =VLOOKUP(Tabela1[[#This Row],[Número]],SAMC!A:F,3,0) -> Mecânica - Betim
A11: SS-97/2025 | B11: IN - 5250-25-011 - Melhoria acesso bloco P 27-TQ-01 K e M - Montagem | C11: IN | D11: =VLOOKUP(Tabela1[[#This Row],[Número]],SAMC!A:F,6,0) -> Em Revisão | E11: 1384640.2 | F11: 361658.9 | G11: =Tabela1[[#This Row],[Valor Global]]-Tabela1[[#This Row],[Faturado Acumulado]] -> 1022981.3 | H11: =VLOOKUP(Tabela1[[#This Row],[Número]],SAMC!A:F,4,0) -> Mecânica e Caldeiraria | I11: =VLOOKUP(Tabela1[[#This Row],[Número]],SAMC!A:F,3,0) -> Mecânica - Betim
A12: SS-98/2025 | B12: IN - 5250-25-012 - Melhoria acesso bloco P 27-TQ-01 L e N - Montagem | C12: IN | D12: =VLOOKUP(Tabela1[[#This Row],[Número]],SAMC!A:F,6,0) -> Em Revisão | E12: 1281329.5 | F12: 485315.66 | G12: =Tabela1[[#This Row],[Valor Global]]-Tabela1[[#This Row],[Faturado Acumulado]] -> 796013.84 | H12: =VLOOKUP(Tabela1[[#This Row],[Número]],SAMC!A:F,4,0) -> Mecânica e Caldeiraria | I12: =VLOOKUP(Tabela1[[#This Row],[Número]],SAMC!A:F,3,0) -> Mecânica - Betim
A13: SS-100/2025 | B13: IN - 5250-24-051 - Melhoria do Acesso aos TQ´s de Escuros 27-TQ-116-A/B - Montagem | C13: IN | D13: =VLOOKUP(Tabela1[[#This Row],[Número]],SAMC!A:F,6,0) -> Em Revisão | E13: 596335.77 | F13: 273778.38 | G13: =Tabela1[[#This Row],[Valor Global]]-Tabela1[[#This Row],[Faturado Acumulado]] -> 322557.4 | H13: =VLOOKUP(Tabela1[[#This Row],[Número]],SAMC!A:F,4,0) -> Mecânica e Caldeiraria | I13: =VLOOKUP(Tabela1[[#This Row],[Número]],SAMC!A:F,3,0) -> Mecânica - Betim
A14: SS-117/2025 | B14: Adequação Escadas de Marinheiro - Projeto | C14: GOG | D14: =VLOOKUP(Tabela1[[#This Row],[Número]],SAMC!A:F,6,0) -> Em Andamento | E14: 202005.1 | F14: 122516.3 | G14: =Tabela1[[#This Row],[Valor Global]]-Tabela1[[#This Row],[Faturado Acumulado]] -> 79488.805 | H14: =VLOOKUP(Tabela1[[#This Row],[Número]],SAMC!A:F,4,0) -> Elaboração de projeto | I14: =VLOOKUP(Tabela1[[#This Row],[Número]],SAMC!A:F,3,0) -> Mecânica - Betim
A15: SS-132/2025 | B15: Envelope Elétrico GPI | C15: GOG | D15: =VLOOKUP(Tabela1[[#This Row],[Número]],SAMC!A:F,6,0) -> Em Andamento | E15: 1257425.7 | F15: 476135.24 | G15: =Tabela1[[#This Row],[Valor Global]]-Tabela1[[#This Row],[Faturado Acumulado]] -> 781290.43 | H15: =VLOOKUP(Tabela1[[#This Row],[Número]],SAMC!A:F,4,0) -> Elétrica e Instrumentação | I15: =VLOOKUP(Tabela1[[#This Row],[Número]],SAMC!A:F,3,0) -> Elétrica e Instrumentação- Betim
A16: SS-133/2025 | B16: IN - 5250-24-085 - Phase-Out do Diesel S500 - Projeto | C16: IN | D16: =VLOOKUP(Tabela1[[#This Row],[Número]],SAMC!A:F,6,0) -> Em Andamento | E16: 486218.33 | F16: 261253.34 | G16: =Tabela1[[#This Row],[Valor Global]]-Tabela1[[#This Row],[Faturado Acumulado]] -> 224964.99 | H16: =VLOOKUP(Tabela1[[#This Row],[Número]],SAMC!A:F,4,0) -> Elaboração de projeto | I16: =VLOOKUP(Tabela1[[#This Row],[Número]],SAMC!A:F,3,0) -> Mecânica - Betim
A17: SS-145/2025 | B17: IN - 5250-24-074 - Adequações para Recebimento de C5+ - Civil | C17: IN | D17: =VLOOKUP(Tabela1[[#This Row],[Número]],SAMC!A:F,6,0) -> Em Andamento | E17: 447354.12 | F17: 34818.052 | G17: =Tabela1[[#This Row],[Valor Global]]-Tabela1[[#This Row],[Faturado Acumulado]] -> 412536.07 | H17: =VLOOKUP(Tabela1[[#This Row],[Número]],SAMC!A:F,4,0) -> Civil | I17: =VLOOKUP(Tabela1[[#This Row],[Número]],SAMC!A:F,3,0) -> Civil (projeto e manutenção civil) - Betim
A18: SS-146/2025 | B18: IN - 5250-24-074 - Adequações para Recebimento de C5+ - Mecânica | C18: IN | D18: =VLOOKUP(Tabela1[[#This Row],[Número]],SAMC!A:F,6,0) -> Em Andamento | E18: 388600.75 | F18: 263974.51 | G18: =Tabela1[[#This Row],[Valor Global]]-Tabela1[[#This Row],[Faturado Acumulado]] -> 124626.24 | H18: =VLOOKUP(Tabela1[[#This Row],[Número]],SAMC!A:F,4,0) -> Mecânica e Caldeiraria | I18: =VLOOKUP(Tabela1[[#This Row],[Número]],SAMC!A:F,3,0) -> Mecânica - Betim
A19: SS-148/2025 | B19: IN - 5250-24-075 - Substituição PLC ALTUS CP4 | C19: IN | D19: =VLOOKUP(Tabela1[[#This Row],[Número]],SAMC!A:F,6,0) -> Em Revisão | E19: 448714.36 | F19: 62291.095 | G19: =Tabela1[[#This Row],[Valor Global]]-Tabela1[[#This Row],[Faturado Acumulado]] -> 386423.27 | H19: =VLOOKUP(Tabela1[[#This Row],[Número]],SAMC!A:F,4,0) -> Elétrica e Instrumentação | I19: =VLOOKUP(Tabela1[[#This Row],[Número]],SAMC!A:F,3,0) -> Elétrica e Instrumentação- Betim
... A190: SS-257/2026 | B190: MODELAGEM 3D - UN-121 | C190: GOG | D190: =VLOOKUP(Tabela1[[#This Row],[Número]],SAMC!A:F,6,0) -> Aguardando classif contabil | E190: 653388.6 | F190: 0 | G190: =Tabela1[[#This Row],[Valor Global]]-Tabela1[[#This Row],[Faturado Acumulado]] -> 653388.6 | H190: =VLOOKUP(Tabela1[[#This Row],[Número]],SAMC!A:F,4,0) -> Civil | I190: =VLOOKUP(Tabela1[[#This Row],[Número]],SAMC!A:F,3,0) -> Civil (projeto e manutenção civil) - Betim
E199: =SUM(Tabela1[Valor Global]) -> 94529688 | F199: =SUM(Tabela1[Faturado Acumulado]) -> 18680533 | G199: =SUM(Tabela1[Valor Saldo]) -> 75849155
G200: ,

Sheet Time line 
B1: TIME LINE - CARTEIRA DE OBRAS | BA1: =TODAY() -> 46189
H2: - | I2: S14 | J2: S15 | K2: S16 | L2: S17 | M2: S18 | N2: S19 | O2: S20 | P2: S21 | Q2: S22 | R2: S23 | S2: S24 | T2: S25 | U2: S26 | V2: S27 | W2: S28 | X2: S29 | Y2: S30 | Z2: S31 | AA2: S32 | AB2: S33 | AC2: S34 | AD2: S35 | AE2: S36 | AF2: S37 | AG2: S38 | AH2: S39 | AI2: S40 | AJ2: S41 | AK2: S42 | AL2: S43 | AM2: S44 | AN2: S45 | AO2: S46 | AP2: S47 | AQ2: S48 | AR2: S49 | AS2: S50 | AT2: S51 | AU2: S52 | AV2: S53 | AW2: S1 | AX2: S2 | AY2: S3 | AZ2: S4
H3: 46188 | I3: =H3+7 -> 46195 | J3: =I3+7 -> 46202 | K3: =J3+7 -> 46209 | L3: =K3+7 -> 46216 | M3: =L3+7 -> 46223 | N3: =M3+7 -> 46230 | O3: =N3+7 -> 46237 | P3: =O3+7 -> 46244 | ... AZ3: =AY3+7 -> 46496
C4: CARTEIRA REGAP | D4: STATUS SAMC | E4: STATUS OBRA | F4: INICIO BL | G4: TERM BL
B5: SS-60/2025 | C5: =VLOOKUP($B5,SAMC!$A:$F,2,0) -> IN-5250-25-014 - ETDI - DESARENADOR | D5: =VLOOKUP($B5,SAMC!$A:$F,5,0) -> Em Andamento | E5: =VLOOKUP($B5,SAMC!$A:$F,6,0) -> Em andamento
B6: SS-61/2025 | C6: =VLOOKUP($B6,SAMC!$A:$F,2,0) -> IN-5250-20-001 - ETDI - REDE CONTAMINADA | D6: =VLOOKUP($B6,SAMC!$A:$F,5,0) -> Em Andamento | E6: =VLOOKUP($B6,SAMC!$A:$F,6,0) -> Em andamento
B7: SS-62/2025 | C7: =VLOOKUP($B7,SAMC!$A:$F,2,0) -> IN - 5250-25-005 - ETDI - FRENTE 01 - BOMBAS DO PPI - ELÉTRICA | D7: =VLOOKUP($B7,SAMC!$A:$F,5,0) -> Em Andamento | E7: =VLOOKUP($B7,SAMC!$A:$F,6,0) -> Em andamento
B8: SS-73/2025 | C8: =VLOOKUP($B8,SAMC!$A:$F,2,0) -> IN - 5250-20-001 - ETDI - BOMBAS DO PPI - CIVIL | D8: =VLOOKUP($B8,SAMC!$A:$F,5,0) -> Em Andamento | E8: =VLOOKUP($B8,SAMC!$A:$F,6,0) -> Em andamento
B9: SS-74/2025 | C9: =VLOOKUP($B9,SAMC!$A:$F,2,0) -> IN-5250-25-015 - ETDI - CONTAMINADA FASE 2 - CIVIL | D9: =VLOOKUP($B9,SAMC!$A:$F,5,0) -> Em Andamento | E9: =VLOOKUP($B9,SAMC!$A:$F,6,0) -> Em andamento
B10: SS-76/2025 | C10: =VLOOKUP($B10,SAMC!$A:$F,2,0) -> IN-5250-23-014 - Novo Laboratório de Integridade da IE | D10: =VLOOKUP($B10,SAMC!$A:$F,5,0) -> Em Revisão | E10: =VLOOKUP($B10,SAMC!$A:$F,6,0) -> Em Revisão
B11: SS-93/2025 | C11: =VLOOKUP($B11,SAMC!$A:$F,2,0) -> Reforço do Muro da APAE | D11: =VLOOKUP($B11,SAMC!$A:$F,5,0) -> Aguardando Planejamento | E11: =VLOOKUP($B11,SAMC!$A:$F,6,0) -> Aguardando classif contabil
B12: SS-94/2025 | C12: =VLOOKUP($B12,SAMC!$A:$F,2,0) -> IN - 5250-20-001 - ETDI - BOMBAS DO PPI - MECANICA | D12: =VLOOKUP($B12,SAMC!$A:$F,5,0) -> Em Andamento | E12: =VLOOKUP($B12,SAMC!$A:$F,6,0) -> Em Andamento
B13: SS-96/2025 | C13: =VLOOKUP($B13,SAMC!$A:$F,2,0) -> IN - 5250-25-010 - Melhoria acesso bloco K 27-TQ-01 C e D - Montagem | D13: =VLOOKUP($B13,SAMC!$A:$F,5,0) -> Em Revisão | E13: =VLOOKUP($B13,SAMC!$A:$F,6,0) -> Em Revisão
B14: SS-97/2025 | C14: =VLOOKUP($B14,SAMC!$A:$F,2,0) -> IN - 5250-25-011 - Melhoria acesso bloco P 27-TQ-01 K e M - Montagem | D14: =VLOOKUP($B14,SAMC!$A:$F,5,0) -> Em Revisão | E14: =VLOOKUP($B14,SAMC!$A:$F,6,0) -> Em Revisão
B15: SS-98/2025 | C15: =VLOOKUP($B15,SAMC!$A:$F,2,0) -> IN - 5250-25-012 - Melhoria acesso bloco P 27-TQ-01 L e N - Montagem | D15: =VLOOKUP($B15,SAMC!$A:$F,5,0) -> Em Revisão | E15: =VLOOKUP($B15,SAMC!$A:$F,6,0) -> Em Revisão
B16: SS-100/2025 | C16: =VLOOKUP($B16,SAMC!$A:$F,2,0) -> IN - 5250-24-051 - Melhoria do Acesso aos TQ´s de Escuros 27-TQ-116-A/B - Montagem | D16: =VLOOKUP($B16,SAMC!$A:$F,5,0) -> Em Revisão | E16: =VLOOKUP($B16,SAMC!$A:$F,6,0) -> Em Revisão
... B199: SS-257/2026 | C199: =VLOOKUP($B199,SAMC!$A:$F,2,0) -> MODELAGEM 3D - UN-121 | D199: =VLOOKUP($B199,SAMC!$A:$F,5,0) -> Aguardando Planejamento | E199: =VLOOKUP($B199,SAMC!$A:$F,6,0) -> Aguardando classif contabil

Sheet SAMC
C1: Categoria SAMC | D1: Tipificação | E1: Status SAMC | F1: Status Real
A2: SS-1/2025 | B2: Manutenção Civil - Março | C2: Civil (projeto e manutenção civil) - Betim | D2: Manuteção Civil-Rotina | E2: Concluída | F2: Concluída
A3: SS-2/2025 | B3: Infraestrutura e Gestão - Mobilização | C3: PLANEJAMENTO E GESTÃO | D3: Parcela de gestão | E3: Concluída | F3: Concluída
A4: SS-3/2025 | B4: Serviço de Apoio - Movimentação de Carga e Disponibilização de Equipamento | C4: PLANEJAMENTO E GESTÃO | D4: Equipamentos | E4: Cancelada | F4: Cancelada
A5: SS-4/2025 | B5: Infraestrutura e Gestão - Parcela Fixa de Gestão | C5: PLANEJAMENTO E GESTÃO | D5: Parcela de gestão | E5: Cancelada | F5: Cancelada
A6: SS-5/2025 | B6: IN - 5250-16-012 - MODERNIZAÇÃO DA PONTE ROLANTE DO COQUE | C6: Mecânica - Betim | D6: Mecânica e Caldeiraria | E6: Cancelada | F6: Cancelada
A7: SS-6/2025 | B7: IN - 5250-24-049 - DESC. CATALISADOR 03V33 P/ SILOS 03V01/02 | C7: Mecânica - Betim | D7: Mecânica e Caldeiraria | E7: Concluída | F7: Concluída
A8: SS-7/2025 | B8: IN - 5250-24-028 - GAT NA UDAV-I | C8: Mecânica - Betim | D8: Mecânica e Caldeiraria | E8: Em Andamento | F8: Concluída
A9: SS-8/2025 | B9: IN - 5250-24-014 - SPDA 38TQ2801AB, 121TQ98CD, 213TQ03 | C9: Elétrica e Instrumentação- Betim | D9: Elétrica e Instrumentação | E9: Cancelada | F9: Cancelada
A10: SS-9/2025 | B10: IN - 5250-19-005 - PT-123 - MODERNIZAÇÃO DA SUBESTAÇÃO | C10: Elétrica e Instrumentação- Betim | D10: Elétrica e Instrumentação | E10: Em Revisão | F10: Concluída
A11: SS-10/2025 | B11: Serviço de Apoio - Movimentação de Carga e Disponibilização de Equipamento - Abril/2025 | C11: PLANEJAMENTO E GESTÃO | D11: Equipamentos | E11: Concluída | F11: Concluída
A12: SS-11/2025 | B12: Infraestrutura e Gestão - Parcela Fixa de Gestão - Abril/2025 | C12: PLANEJAMENTO E GESTÃO | D12: Parcela de gestão | E12: Concluída | F12: Concluída
A13: SS-12/2025 | B13: Manutenção Civil - Rotina - Abril/2025 | C13: Civil (projeto e manutenção civil) - Betim | D13: Manuteção Civil-Rotina | E13: Concluída | F13: Concluída
... A228: SS-227/2025 | B228: Acesso ao Tanque 01A | C228: Civil (projeto e manutenção civil) - Betim | D228: Civil | E228: Em Andamento | F228: Concluída
A229: SS-228/2025 | B229: IN - 5250-17-007 - MODERNIZAÇÃO TURBO EXPANSOR 103-TG-01 - ELÉTRICA | C229: Elétrica e Instrumentação- Betim | D229: Elétrica e Instrumentação | E229: Aguardando Aprovação da Revisão | F229: =E229 -> Aguardando Aprovação da Revisão
A230: SS-229/2025 | B230: IN - 5250-17-007 - LIBERAÇÃO 103-TG-01 | C230: Mecânica - Betim | D230: Mecânica e Caldeiraria | E230: Em Andamento | F230: Em Andamento
A231: SS-230/2025 | B231: Acesso ao Tanque 36C, F e G | C231: Civil (projeto e manutenção civil) - Betim | D231: Civil | E231: Em Andamento | F231: Concluída
A232: SS-231/2025 | B232: Apoio ao SMS | C232: Elétrica e Instrumentação- Betim | D232: Elétrica e Instrumentação | E232: Concluída | F232: Concluída
A233: SS-232/2025 | B233: IN-5250-25-015 - ETDI - CONTAMINADA FASE 2 - BENS | C233: Receber Materiais - Regap-Betim | D233: Revenda Materiais | E233: Em Andamento | F233: Concluída
A234: SS-233/2025 | B234: IN - 5250-25-005 - ETDI - FRENTE 01 - BOMBAS DO PPI - ELÉTRICA - Bens | C234: Receber Materiais - Regap-Betim | D234: Revenda Materiais | E234: Aguardando Aprovação | F234: =E234 -> Aguardando Aprovação
A235: SS-234/2025 | B235: Apoio DATA BOOK - Até Novembro/2025 | C235: PLANEJAMENTO E GESTÃO | D235: Civil | E235: Cancelada | F235: Cancelada
A236: SS-235/2025 | B236: Apoio ao S2 | C236: Elétrica e Instrumentação- Betim | D236: Elétrica e Instrumentação | E236: Em Revisão | F236: Em Revisão
A237: SS-236/2025 | B237: Apoio ao GPI | C237: Elétrica e Instrumentação- Betim | D237: Elétrica e Instrumentação | E237: Em Andamento | F237: Concluída
A238: SS-1/2026 | B238: Adequação Escadas de Marinheiro - Execução | C238: Civil (projeto e manutenção civil) - Betim | D238: Civil | E238: Em Andamento | F238: Em Andamento
A239: SS-2/2026 | B239: IN-5250-24-092 - PT-200 - Escavação Manual para Pré Furos e Fundação | C239: Civil (projeto e manutenção civil) - Betim | D239: Civil | E239: Em Andamento | F239: Em Andamento
A240: SS-3/2026 | B240: Escaneamento a laser da Unidade U-121 | C240: Civil (projeto e manutenção civil) - Betim | D240: Civil | E240: Em Andamento | F240: Concluída
A241: SS-4/2026 | B241: IN-5250-24-013 - ALIMENTAÇÕES PROVISÓRIAS TAF - SDCD CCF-I | C241: Elétrica e Instrumentação- Betim | D241: Elétrica e Instrumentação | E241: Em Andamento | F241: Em Andamento
A242: SS-5/2026 | B242: IN-5250-23-017 - Sondagem Revamp | C242: Civil (projeto e manutenção civil) - Betim | D242: Civil | E242: Aguardando Aprovação da Revisão | F242: =E242 -> Aguardando Aprovação da Revisão
A243: SS-6/2026 | B243: Georadar Revamp | C243: Civil (projeto e manutenção civil) - Betim | D243: Civil | E243: Aguardando Planejamento | F243: Concluída
A244: SS-7/2026 | B244: Georadar PT-200 | C244: Civil (projeto e manutenção civil) - Betim | D244: Civil | E244: Cancelada | F244: Cancelada
A245: SS-8/2026 | B245: Adequação Escadas de Marinheiro - Execução UDAV 01/02 | C245: Civil (projeto e manutenção civil) - Betim | D245: Civil | E245: Em Andamento | F245: Em Andamento
A246: SS-9/2026 | B246: Adequação Escadas de Marinheiro - Fornecimento de Bens | C246: Receber Materiais - Regap-Betim | D246: Revenda Materiais | E246: Em Andamento | F246: Em Andamento
A247: SS-10/2026 | B247: Infraestrutura e Gestão - Parcela Fixa de Gestão - Fevereiro/2026 | C247: PLANEJAMENTO E GESTÃO | D247: Parcela de gestão | E247: Concluída | F247: Concluída
A248: SS-11/2026 | B248: Serviço de Apoio - Movimentação de Carga e Disponibilização de Equipamento - Fevereiro/2026 | C248: PLANEJAMENTO E GESTÃO | D248: Equipamentos | E248: Concluída | F248: Concluída
A249: SS-12/2026 | B249: Manutenção Civil - Rotina - Fevereiro/2026 | C249: Civil (projeto e manutenção civil) - Betim | D249: Manuteção Civil-Rotina | E249: Concluída | F249: Concluída
A250: SS-13/2026 | B250: Apoio de HS - Mecânica - Fevereiro/2026 | C250: Mecânica - Betim | D250: Apoio - HS | E250: Concluída | F250: Concluída
A251: SS-14/2026 | B251: PMBC - 5250-26-100 - ALTERAÇÕES - HAZOP DA U-001 E U-101 | C251: Mecânica - Betim | D251: Mecânica e Caldeiraria | E251: Em Andamento | F251: Em Andamento
A252: SS-15/2026 | B252: Apoio de HS - Andaime - Fevereiro/2026 | C252: Mecânica - Betim | D252: Apoio - HS | E252: Concluída | F252: Concluída
A253: SS-16/2026 | B253: PMBC - 5250-26-100 - HAZOP DA U-001 E U-101 - BENS | C253: Receber Materiais - Regap-Betim | D253: Revenda Materiais | E253: Em Andamento | F253: Em Andamento
A254: SS-17/2026 | B254: Apoio de HS - Elétrica/Instrumentação - Fevereiro/2026 | C254: Elétrica e Instrumentação- Betim | D254: Apoio - HS | E254: Concluída | F254: Concluída
...

Sheet Time line  (2)
B1: TIME LINE - CARTEIRA DE OBRAS | BA1: =TODAY() -> 46189
I2: S14 | J2: S15 | K2: S16 | L2: S17 | M2: S18 | N2: S19 | O2: S20 | P2: S21 | Q2: S22 | R2: S23 | S2: S24 | T2: S25 | U2: S26 | V2: S27 | W2: S28 | X2: S29 | Y2: S30 | Z2: S31 | AA2: S32 | AB2: S33 | AC2: S34 | AD2: S35 | AE2: S36 | AF2: S37 | AG2: S38 | AH2: S39 | AI2: S40 | AJ2: S41 | AK2: S42 | AL2: S43 | AM2: S44 | AN2: S45 | AO2: S46 | AP2: S47 | AQ2: S48 | AR2: S49 | AS2: S50 | AT2: S51 | AU2: S52 | AV2: S53 | AW2: S1 | AX2: S2 | AY2: S3 | AZ2: S4
H3: 45791 | I3: 46111 | J3: =I3+7 -> 46118 | K3: =J3+7 -> 46125 | L3: =K3+7 -> 46132 | M3: =L3+7 -> 46139 | N3: =M3+7 -> 46146 | O3: =N3+7 -> 46153 | P3: =O3+7 -> 46160 | Q3: =P3+7 -> 46167 | ... AZ3: =AY3+7 -> 46412
C4: CARTEIRA REGAP | D4: STATUS SAMC | E4: STATUS OBRA | F4: INICIO BL | G4: TERM BL
B5: SS-76/2025 | C5: IN-5250-23-014 - Novo Laboratório de Integridade da IE | D5: Em Andamento | E5: EM REPLANEJAMENTO | F5: =VLOOKUP($B5,'Base dados'!$A:$K,10,0) -> 0 | G5: =VLOOKUP($B5,'Base dados'!$A:$K,11,0) -> 0
B6: SS-96/2025 | C6: IN - 5250-25-010 - Melhoria acesso bloco K 27-TQ-01 C e D - Montagem | D6: Em Andamento | E6: EM REPLANEJAMENTO | F6: =VLOOKUP($B6,'Base dados'!$A:$K,10,0) -> 0 | G6: =VLOOKUP($B6,'Base dados'!$A:$K,11,0) -> 0
B7: SS-97/2025 | C7: IN - 5250-25-011 - Melhoria acesso bloco P 27-TQ-01 K e M - Montagem | D7: Em Andamento | E7: EM REPLANEJAMENTO | F7: =VLOOKUP($B7,'Base dados'!$A:$K,10,0) -> 0 | G7: =VLOOKUP($B7,'Base dados'!$A:$K,11,0) -> 0
B8: SS-98/2025 | C8: IN - 5250-25-012 - Melhoria acesso bloco P 27-TQ-01 L e N - Montagem | D8: Em Andamento | E8: EM REPLANEJAMENTO | F8: =VLOOKUP($B8,'Base dados'!$A:$K,10,0) -> 0 | G8: =VLOOKUP($B8,'Base dados'!$A:$K,11,0) -> 0
B9: SS-100/2025 | C9: IN - 5250-24-051 - Melhoria do Acesso aos TQ´s de Escuros 27-TQ-116-A/B - Montagem | D9: Em Andamento | E9: EM REPLANEJAMENTO | F9: =VLOOKUP($B9,'Base dados'!$A:$K,10,0) -> 0 | G9: =VLOOKUP($B9,'Base dados'!$A:$K,11,0) -> 0
B10: SS-132/2025 | C10: Envelope Elétrico GPI | D10: Aguardando Aprovação da Revisão | E10: EM REPLANEJAMENTO | F10: =VLOOKUP($B10,'Base dados'!$A:$K,10,0) -> 0 | G10: =VLOOKUP($B10,'Base dados'!$A:$K,11,0) -> 0
B11: SS-145/2025 | C11: IN - 5250-24-074 - Adequações para Recebimento de C5+ - Civil | D11: Em Andamento | E11: EM REPLANEJAMENTO | F11: =VLOOKUP($B11,'Base dados'!$A:$K,10,0) -> 0 | G11: =VLOOKUP($B11,'Base dados'!$A:$K,11,0) -> 0
B12: SS-146/2025 | C12: IN - 5250-24-074 - Adequações para Recebimento de C5+ - Mecânica | D12: Em Andamento | E12: EM REPLANEJAMENTO | F12: =VLOOKUP($B12,'Base dados'!$A:$K,10,0) -> 0 | G12: =VLOOKUP($B12,'Base dados'!$A:$K,11,0) -> 0
B13: SS-147/2025 | C13: IN - 5250-24-074 - Adequações para Recebimento de C5+ - Elétrica | D13: Em Revisão | E13: EM REPLANEJAMENTO | F13: =VLOOKUP($B13,'Base dados'!$A:$K,10,0) -> #N/A | G13: =VLOOKUP($B13,'Base dados'!$A:$K,11,0) -> #N/A
B14: SS-166/2025 | C14: IN - 5250-25-010 - Melhoria acesso bloco K 27-TQ-01 E - Montagem | D14: Em Andamento | E14: EM REPLANEJAMENTO | F14: =VLOOKUP($B14,'Base dados'!$A:$K,10,0) -> 0 | G14: =VLOOKUP($B14,'Base dados'!$A:$K,11,0) -> 0
B15: SS-171/2025 | C15: IN - 5250-24-051 - Melhoria do Acesso aos TQ´s de Escuros 27-TQ-116-C/E - Montagem | D15: Em Andamento | E15: EM REPLANEJAMENTO | F15: =VLOOKUP($B15,'Base dados'!$A:$K,10,0) -> 0 | G15: =VLOOKUP($B15,'Base dados'!$A:$K,11,0) -> 0
B16: SS-172/2025 | C16: IN - 5250-24-051 - Melhoria do Acesso aos TQ´s de Escuros 27-TQ-116-D/F - Montagem | D16: Em Andamento | E16: EM REPLANEJAMENTO | F16: =VLOOKUP($B16,'Base dados'!$A:$K,10,0) -> 0 | G16: =VLOOKUP($B16,'Base dados'!$A:$K,11,0) -> 0
... B39: SS-190/2025 | C39: IN-5250-25-100 - ELÉTRICA - ADAPTAÇÕES PARA VENDA DIRETA DE DIESEL | D39: Em Andamento | E39: EM ANDAMENTO | F39: =VLOOKUP($B39,'Base dados'!$A:$K,10,0) -> #N/A | G39: =VLOOKUP($B39,'Base dados'!$A:$K,11,0) -> #N/A
B40: SS-1/2026 | C40: Adequação Escadas de Marinheiro - Execução | D40: Em Andamento | E40: EM ANDAMENTO | F40: 46034 | G40: 46113
B41: SS-2/2026 | C41: PT-200 - Escavação Manual para Pré Furos e Fundação | D41: Em Andamento | E41: EM ANDAMENTO | F41: =VLOOKUP($B41,'Base dados'!$A:$K,10,0) -> 0 | G41: =VLOOKUP($B41,'Base dados'!$A:$K,11,0) -> 0
B42: SS-3/2026 | C42: Escaneamento a laser da Unidade U-121 | D42: Em Andamento | E42: EM ANDAMENTO | F42: =VLOOKUP($B42,'Base dados'!$A:$K,10,0) -> #N/A | G42: =VLOOKUP($B42,'Base dados'!$A:$K,11,0) -> #N/A
B43: SS-4/2026 | C43: IN-5250-24-013 - ALIMENTAÇÕES PROVISÓRIAS TAF - SDCD CCF-I | D43: Em Andamento | E43: EM ANDAMENTO | F43: =VLOOKUP($B43,'Base dados'!$A:$K,10,0) -> 0 | G43: =VLOOKUP($B43,'Base dados'!$A:$K,11,0) -> 0
B44: SS-8/2026 | C44: Adequação Escadas de Marinheiro - Execução UDAV 01/02 | D44: Em Andamento | E44: EM ANDAMENTO | F44: =VLOOKUP($B44,'Base dados'!$A:$K,10,0) -> 0 | G44: =VLOOKUP($B44,'Base dados'!$A:$K,11,0) -> 0
B45: SS-14/2026 | C45: PMBC - 5250-26-100 - ALTERAÇÕES - HAZOP DA U-001 E U-101 | D45: Encaminhado p/ o fornecedor | E45: INICIO CURTO PRAZO | F45: =VLOOKUP($B45,'Base dados'!$A:$K,10,0) -> 0 | G45: =VLOOKUP($B45,'Base dados'!$A:$K,11,0) -> 0
B46: SS-36/2026 | C46: Manutenção Civil - Linha do Flare na Av. 8 | D46: Em Andamento | E46: EM ANDAMENTO | F46: =VLOOKUP($B46,'Base dados'!$A:$K,10,0) -> 0 | G46: =VLOOKUP($B46,'Base dados'!$A:$K,11,0) -> 0
B47: SS-39/2026 | C47: IN-5250-24-092 - PT-200 - Estrutura Metálica - Fabricação | D47: Encaminhado p/ o fornecedor | E47: EM ANDAMENTO | F47: =VLOOKUP($B47,'Base dados'!$A:$K,10,0) -> 0 | G47: =VLOOKUP($B47,'Base dados'!$A:$K,11,0) -> 0
B48: SS-41/2026 | C48: IN-5250-24-092 - PT-200 - Civil e Fundações | D48: Aguardando Class Contabil | E48: INICIO CURTO PRAZO | F48: =VLOOKUP($B48,'Base dados'!$A:$K,10,0) -> 0 | G48: =VLOOKUP($B48,'Base dados'!$A:$K,11,0) -> 0
B49: SS-42/2026 | C49: IN-5250-24-092 - PT-200 - Civil e Arquitetura | D49: Aguardando Class Contabil | E49: INICIO MEDIO PRAZO | F49: =VLOOKUP($B49,'Base dados'!$A:$K,10,0) -> 0 | G49: =VLOOKUP($B49,'Base dados'!$A:$K,11,0) -> 0
B50: SS-44/2026 | C50: IN - 5250-24-085 - Phase-Out do Diesel S500 - Mudança 2.1 - Fabricação (Tubovias) | D50: Encaminhado p/ o fornecedor | E50: EM ANDAMENTO | F50: =VLOOKUP($B50,'Base dados'!$A:$K,10,0) -> 0 | G50: =VLOOKUP($B50,'Base dados'!$A:$K,11,0) -> 0
B51: SS-45/2026 | C51: IN - 5250-24-085 - Phase-Out do Diesel S500 - Mudança 2.1 - Montagem (Tubovias) | D51: Aguardando Class Contabil | E51: INICIO CURTO PRAZO | F51: =VLOOKUP($B51,'Base dados'!$A:$K,10,0) -> 0 | G51: =VLOOKUP($B51,'Base dados'!$A:$K,11,0) -> 0
B52: SS-63/2026 | C52: Rede Envelopada - Armazéns S5 x S6 | D52: Aguardando Aprovação | E52: INICIO CURTO PRAZO | F52: =VLOOKUP($B52,'Base dados'!$A:$K,10,0) -> 0 | G52: =VLOOKUP($B52,'Base dados'!$A:$K,11,0) -> 0
... B90: SS-139/2026 | C90: UN-623 - CASA DE QUÍMICOS - FORNECIMENTO DE BENS | D90: Aguardando Planejamento | E90: MATERIAIS | F90: =VLOOKUP($B90,'Base dados'!$A:$K,10,0) -> 0 | G90: =VLOOKUP($B90,'Base dados'!$A:$K,11,0) -> 0

Sheet Dashboards
A2: PAINEL DE GESTÃO - SS'S
B5: 2025 | C5: SERVIÇOS | D5: MATERIAIS | E5: TOTAL | F5: ACUM | H5: Número | I5: Descrição | J5: Saldo (R$) | K5: Acum | L5: %
B6: MAR | C6: 733754.87 | E6: =SUM(C6:D6) -> 733754.87 | F6: =E6 -> 733754.87 | H6: SS-39/2026 | I6: IN-5250-24-092 - PT-200 - Estrutura Metálica - Fabricação | J6: 7296261.9 | K6: =J6 -> 7296261.9 | L6: =K6/$J$22 -> 0.15139161
B7: ABR | C7: 2230893.7 | E7: =SUM(C7:D7) -> 2230893.7 | F7: =F6+E7 -> 2964648.6 | H7: SS-40/2026 | I7: IN-5250-24-092 - PT-200 - Estrutura Metálica - Montagem | J7: 5251157.2 | K7: =K6+J7 -> 12547419 | L7: =K7/$J$22 -> 0.26034893
B8: MAI | C8: 2433386.6 | E8: =SUM(C8:D8) -> 2433386.6 | F8: =F7+E8 -> 5398035.2 | H8: SS-38/2026 | I8: IN-5250-24-092 - PT-200 - Estrutura Metálica - Fornecimento de Bens | J8: 3219797 | K8: =K7+J8 -> 15767216 | L8: =K8/$J$22 -> 0.32715715
B9: JUN | C9: 4385798.7 | E9: =SUM(C9:D9) -> 4385798.7 | F9: =F8+E9 -> 9783834 | H9: SS-51/2026 | I9: Serviço de Apoio - Movimentação de Carga e Disponibilização de Equipamento - Abril/2026 | J9: 2820563.7 | K9: =K8+J9 -> 18587780 | L9: =K9/$J$22 -> 0.3856816
B10: JUL | C10: 7576876 | E10: =SUM(C10:D10) -> 7576876 | F10: =F9+E10 -> 17360710 | H10: SS-74/2025 | I10: IN - 5250-20-001 - ETDI - CONTAMINADA FASE 2 - CIVIL | J10: 1658914.8 | K10: =K9+J10 -> 20246695 | L10: =K10/$J$22 -> 0.42010276
B11: AGO | C11: 8969356.1 | E11: =SUM(C11:D11) -> 8969356.1 | F11: =F10+E11 -> 26330066 | H11: SS-90/2026 | I11: Manutenção Civil - CANAL DE PINTADOS | J11: 1565744.9 | K11: =K10+J11 -> 21812439 | L11: =K11/$J$22 -> 0.45259071
B12: SET | C12: 7293856.4 | E12: =SUM(C12:D12) -> 7293856.4 | F12: =F11+E12 -> 33623922 | H12: SS-41/2026 | I12: IN-5250-24-092 - PT-200 - Civil e Fundações | J12: 1382059 | K12: =K11+J12 -> 23194498 | L12: =K12/$J$22 -> 0.48126733
B13: OUT | C13: 10796477 | D13: 711274.82 | E13: =SUM(C13:D13) -> 11507751 | F13: =F12+E13 -> 45131674 | H13: SS-76/2025 | I13: IN-5250-23-014 - Novo Laboratório de Integridade da IE | J13: 1264392.7 | K13: =K12+J13 -> 24458891 | L13: =K13/$J$22 -> 0.50750247
B14: NOV | C14: 6366437.1 | D14: 1618995.3 | E14: =SUM(C14:D14) -> 7985432.5 | F14: =F13+E14 -> 53117106 | H14: SS-50/2026 | I14: Infraestrutura e Gestão - Parcela Fixa de Gestão - Abril/2026 | J14: 1198055.6 | K14: =K13+J14 -> 25656947 | L14: =K14/$J$22 -> 0.53236117
B15: DEZ | C15: 9580955.6 | D15: 1251326.7 | E15: =SUM(C15:D15) -> 10832282 | F15: =F14+E15 -> 63949389 | H15: SS-110/2026 | I15: IN - 5250-24-085 - Phase-Out do Diesel S500 - Mudança 4.1 - Montagem (Tubovias) | J15: 1158558.4 | K15: =K14+J15 -> 26815505 | L15: =K15/$J$22 -> 0.55640033
B16: PERIODO | C16: SERVIÇOS | D16: MATERIAIS | E16: TOTAL | F16: ACUM | H16: SS-45/2026 | I16: IN - 5250-24-085 - Phase-Out do Diesel S500 - Mudança 2.1 - Montagem (Tubovias) | J16: 1134057.8 | K16: =K15+J16 -> 27949563 | L16: =K16/$J$22 -> 0.57993113
B17: 2025 | C17: =SUM(C6:C15) -> 60367792 | D17: =SUM(D6:D15) -> 3581596.9 | E17: =SUM(C17:D17) -> 63949389 | F17: =E17 -> 63949389 | H17: SS-89/2026 | I17: Manutenção Civil - PÁTIO DE ENXOFRE | J17: 1035416.1 | K17: =K16+J17 -> 28984979 | L17: =K17/$J$22 -> 0.60141519
B18: 2026 | C18: =SUM(C19:C21) -> 19606011 | D18: =SUM(D19:D21) -> 394684.52 | E18: =SUM(C18:D18) -> 20000695 | F18: =F17+E18 -> 83950084
B19: JAN | C19: 6789699.1 | D19: 249691.01 | E19: =SUM(C19:D19) -> 7039390.1 | F19: =F15+E19 -> 70988779
B20: FEV | C20: 6083463.8 | D20: 60502.94 | E20: =SUM(C20:D20) -> 6143966.7 | F20: =F19+E20 -> 77132745
B21: MAR | C21: 6732847.7 | D21: 84490.57 | E21: =SUM(C21:D21) -> 6817338.3 | F21: =F20+E21 -> 83950084 | I21: Total Geral | J21: =SUM(J6:J20) -> 28984979
I22: Saldo Carteira SAMC | J22: 48194624
C26: =B17 -> 2025 | D26: =B18 -> 2026
B27: =C16 -> SERVIÇOS | C27: =C17 -> 60367792 | D27: =C18 -> 19606011
B28: =D16 -> MATERIAIS | C28: =D17 -> 3581596.9 | D28: =D18 -> 394684.52 | R28: 6083463.8
B29: =E16 -> TOTAL | C29: =SUM(C27:C28) -> 63949389 | D29: =SUM(D27:D28) -> 20000695
R30: 6732847.7
